Workbook

Sheet Start Here
A1: TechSentinals CRM — Start Here
A2: A simple daily workflow for services and products. Enter data only in the two yellow input sheets; the other tabs update automatically.
A4: Daily workflow
A5: 1 | B5: Add every new opportunity in Master Leads.
A6: 2 | B6: Use Contact Log when you want a dated history of calls, WhatsApp, email, meetings, demos, proposals, or visits.
A7: 3 | B7: Update Last Contact, Next Follow-Up, Next Action, Follow-Up Round, Priority, and Sales Stage after each interaction.
A8: 4 | B8: Set Market to India or Foreign. Enter Deal Value as an INR equivalent so pipeline totals remain comparable.
A9: 5 | B9: When won, set Sales Stage to Converted and enter Conversion/Close Date. For non-wins, use Closed or Lost and record the reason.
A10: 6 | B10: Use Follow Ups every day for due and overdue work. Use department/product tabs as read-only views.
A11: 7 | B11: Dashboard and analytics tabs are formula-driven. Avoid typing in gray formula areas.
A12: 8 | B12: Replace Owner 1 / Owner 2 / Owner 3 with team names in the dropdown settings when ready.
A14: Definitions that keep the analytics clean
A15: Field | B15: Use it for | C15: Examples
A16: Priority | B16: How urgently the lead deserves attention | C16: Hot / Medium / Cold
A17: Follow-Up Round | B17: Where the contact sequence currently stands | C17: 1st / 2nd / 3rd Follow-Up
A18: Sales Stage | B18: Where the commercial opportunity stands | C18: Qualified / Proposal Sent / Negotiation
A19: Converted | B19: Won and became a customer | C19: Enter the conversion date
A20: Closed / Lost | B20: No active opportunity; not a conversion | C20: Add the reason for learning

Sheet Master Leads
A1: Master Leads — Main Data Entry
A2: One row per lead. Yellow/white cells are for entry; gray columns are calculated automatically. Keep all leads here so every view and dashboard stays synchronized.
A3: Required for useful reporting: Lead ID, Date Added, Company/Person, Market, Business Side, Department/Product, Lead Source, Priority, Sales Stage, and Assigned To.
A5: Lead ID | B5: Date Added | C5: Company / Person | D5: Contact Person | E5: Phone / WhatsApp | F5: Email | G5: City | H5: Country | I5: Market | J5: Business Side | K5: Department / Product | L5: Category | M5: Requirement / Interested In | N5: Lead Source | O5: Assigned To | P5: Priority | Q5: Sales Stage | R5: Follow-Up Round | S5: Last Contact Date | T5: Next Follow-Up Date | U5: Follow-Up Status | V5: Next Action | W5: Meeting / Demo Date | X5: Proposal Date | Y5: Deal Value (INR) | Z5: Probability | AA5: Weighted Pipeline | AB5: Conversion / Close Date | AC5: Lost / Closed Reason | AD5: Notes | AE5: Lead Month | AF5: Conversion Month | AG5: Open? | AH5: Converted? | AI5: Follow-Up Due?
A6: 1 | B6: 46264 | C6: Inventa | D6: Darshit | E6: 7285043792 | F6: inventasys@gmail.com | G6: Ahmedabad | H6: India | I6: India | J6: Service | K6: Healthcare | L6: Pharma | N6: Event/Expo | O6: Aastha | P6: Medium | Q6: Converted | R6: Follow-Up Complete | S6: 46254 | U6: =IF($A6="","",IF(OR($Q6="Converted",$Q6="Closed",$Q6="Lost"),"Completed",IF($T6="","Not Scheduled",IF($T6<TODAY(),"Overdue",IF($T6=TODAY(),"Due Today","Upcoming"))))) -> Completed | Z6: 0.1 | AA6: =IF($A6="","",IFERROR($Y6*$Z6,0)) -> 0 | AB6: 46235 | AE6: =IF($B6="","",DATE(YEAR($B6),MONTH($B6),1)) -> 46235 | AF6: =IF($AB6="","",DATE(YEAR($AB6),MONTH($AB6),1)) -> 46235 | AG6: =IF($A6="","",IF(OR($Q6="Converted",$Q6="Closed",$Q6="Lost"),"No","Yes")) -> No | AH6: =IF($A6="","",IF($Q6="Converted","Yes","No")) -> Yes | AI6: =IF($A6="","",IF(OR($U6="Overdue",$U6="Due Today"),"Yes","No")) -> No
A7: 2 | B7: 46264 | C7: Rototech | D7: Jignesh Patel | E7: 9998447948 | F7: patel.jignesh1985@gmail.com | G7: Ahmedabad | H7: India | I7: India | J7: Service | K7: Manufacturing | L7: Manufacturing | N7: Existing Client | O7: Aastha | P7: Hot | Q7: Converted | R7: Follow-Up Complete | S7: 46259 | U7: =IF($A7="","",IF(OR($Q7="Converted",$Q7="Closed",$Q7="Lost"),"Completed",IF($T7="","Not Scheduled",IF($T7<TODAY(),"Overdue",IF($T7=TODAY(),"Due Today","Upcoming"))))) -> Completed | AA7: =IF($A7="","",IFERROR($Y7*$Z7,0)) -> 0 | AE7: =IF($B7="","",DATE(YEAR($B7),MONTH($B7),1)) -> 46235 | AF7: 46235 | AG7: =IF($A7="","",IF(OR($Q7="Converted",$Q7="Closed",$Q7="Lost"),"No","Yes")) -> No | AH7: =IF($A7="","",IF($Q7="Converted","Yes","No")) -> Yes | AI7: =IF($A7="","",IF(OR($U7="Overdue",$U7="Due Today"),"Yes","No")) -> No
A8: 3 | B8: 46264 | C8: Meteoric Pharma | D8: Mithun Acharya | E8: 9227996623 | F8: mithun.it@meteoricbiopharma.com | G8: Ahmedabad | H8: India | I8: India | J8: Service | K8: Healthcare | L8: Pharma | N8: Cold Outreach | O8: Aastha | P8: Hot | Q8: Proposal Sent | R8: Initial Contact | S8: 46272 | U8: =IF($A8="","",IF(OR($Q8="Converted",$Q8="Closed",$Q8="Lost"),"Completed",IF($T8="","Not Scheduled",IF($T8<TODAY(),"Overdue",IF($T8=TODAY(),"Due Today","Upcoming"))))) -> Not Scheduled | AA8: =IF($A8="","",IFERROR($Y8*$Z8,0)) -> 0 | AE8: =IF($B8="","",DATE(YEAR($B8),MONTH($B8),1)) -> 46235 | AF8: =IF($AB8="","",DATE(YEAR($AB8),MONTH($AB8),1)) | AG8: =IF($A8="","",IF(OR($Q8="Converted",$Q8="Closed",$Q8="Lost"),"No","Yes")) -> Yes | AH8: =IF($A8="","",IF($Q8="Converted","Yes","No")) -> No | AI8: =IF($A8="","",IF(OR($U8="Overdue",$U8="Due Today"),"Yes","No")) -> No
A9: 4 | B9: 46264 | C9: Vishalwin | D9: Mayuri | E9: 9510779939 | F9: puunam@vishalwinfoundation.org/ puunam@vishalwinfoundation.org | G9: Ahmedabad | H9: India | I9: India | J9: Service | K9: NGO & Foundation | L9: NGO | N9: Cold Outreach | O9: Aastha | P9: Hot | Q9: Converted | R9: Follow-Up Complete | S9: 46273 | U9: =IF($A9="","",IF(OR($Q9="Converted",$Q9="Closed",$Q9="Lost"),"Completed",IF($T9="","Not Scheduled",IF($T9<TODAY(),"Overdue",IF($T9=TODAY(),"Due Today","Upcoming"))))) -> Completed | AA9: =IF($A9="","",IFERROR($Y9*$Z9,0)) -> 0 | AE9: =IF($B9="","",DATE(YEAR($B9),MONTH($B9),1)) -> 46235 | AF9: =IF($AB9="","",DATE(YEAR($AB9),MONTH($AB9),1)) | AG9: =IF($A9="","",IF(OR($Q9="Converted",$Q9="Closed",$Q9="Lost"),"No","Yes")) -> No | AH9: =IF($A9="","",IF($Q9="Converted","Yes","No")) -> Yes | AI9: =IF($A9="","",IF(OR($U9="Overdue",$U9="Due Today"),"Yes","No")) -> No
A10: 5 | B10: 46264 | C10: Acme Industries | D10: Ketan Shah | E10: 9825060677 | G10: Ahmedabad | H10: India | I10: India | J10: Service | K10: Manufacturing | L10: Manufacturing | N10: Cold Outreach | O10: Aastha | P10: Cold | Q10: Lost | R10: Follow-Up Complete | U10: =IF($A10="","",IF(OR($Q10="Converted",$Q10="Closed",$Q10="Lost"),"Completed",IF($T10="","Not Scheduled",IF($T10<TODAY(),"Overdue",IF($T10=TODAY(),"Due Today","Upcoming"))))) -> Completed | AA10: =IF($A10="","",IFERROR($Y10*$Z10,0)) -> 0 | AE10: =IF($B10="","",DATE(YEAR($B10),MONTH($B10),1)) -> 46235 | AF10: =IF($AB10="","",DATE(YEAR($AB10),MONTH($AB10),1)) | AG10: =IF($A10="","",IF(OR($Q10="Converted",$Q10="Closed",$Q10="Lost"),"No","Yes")) -> No | AH10: =IF($A10="","",IF($Q10="Converted","Yes","No")) -> No | AI10: =IF($A10="","",IF(OR($U10="Overdue",$U10="Due Today"),"Yes","No")) -> No
A11: 6 | B11: 46264 | C11: Strikar | D11: Mitali | E11: 9773433064 | G11: Ahmedabad | H11: India | I11: India | J11: Service | K11: Healthcare | L11: Other Healthcare | N11: Event/Expo | O11: Aastha | P11: Hot | Q11: Converted | R11: Follow-Up Complete | S11: 46272 | U11: =IF($A11="","",IF(OR($Q11="Converted",$Q11="Closed",$Q11="Lost"),"Completed",IF($T11="","Not Scheduled",IF($T11<TODAY(),"Overdue",IF($T11=TODAY(),"Due Today","Upcoming"))))) -> Completed | AA11: =IF($A11="","",IFERROR($Y11*$Z11,0)) -> 0 | AE11: =IF($B11="","",DATE(YEAR($B11),MONTH($B11),1)) -> 46235 | AF11: =IF($AB11="","",DATE(YEAR($AB11),MONTH($AB11),1)) | AG11: =IF($A11="","",IF(OR($Q11="Converted",$Q11="Closed",$Q11="Lost"),"No","Yes")) -> No | AH11: =IF($A11="","",IF($Q11="Converted","Yes","No")) -> Yes | AI11: =IF($A11="","",IF(OR($U11="Overdue",$U11="Due Today"),"Yes","No")) -> No
A12: 7 | B12: 46264 | C12: Divyang Opticals | D12: Divyang | E12: 9825403704 | G12: Ahmedabad | H12: India | I12: India | J12: Service | K12: Optical | L12: Optical/Eyewear | N12: Cold Outreach | O12: Aastha | P12: Hot | Q12: Negotiation | R12: 3rd Follow-Up | S12: 46270 | U12: =IF($A12="","",IF(OR($Q12="Converted",$Q12="Closed",$Q12="Lost"),"Completed",IF($T12="","Not Scheduled",IF($T12<TODAY(),"Overdue",IF($T12=TODAY(),"Due Today","Upcoming"))))) -> Not Scheduled | AA12: =IF($A12="","",IFERROR($Y12*$Z12,0)) -> 0 | AE12: =IF($B12="","",DATE(YEAR($B12),MONTH($B12),1)) -> 46235 | AF12: =IF($AB12="","",DATE(YEAR($AB12),MONTH($AB12),1)) | AG12: =IF($A12="","",IF(OR($Q12="Converted",$Q12="Closed",$Q12="Lost"),"No","Yes")) -> Yes | AH12: =IF($A12="","",IF($Q12="Converted","Yes","No")) -> No | AI12: =IF($A12="","",IF(OR($U12="Overdue",$U12="Due Today"),"Yes","No")) -> No
A13: 8 | B13: 46264 | C13: Karma Foundation | D13: Sagar | E13: 9898760976 | G13: Ahmedabad | H13: India | I13: India | J13: Service | K13: NGO & Foundation | L13: Foundation | N13: Other | O13: Aastha | P13: Hot | Q13: Negotiation | R13: 3rd Follow-Up | S13: 46272 | U13: =IF($A13="","",IF(OR($Q13="Converted",$Q13="Closed",$Q13="Lost"),"Completed",IF($T13="","Not Scheduled",IF($T13<TODAY(),"Overdue",IF($T13=TODAY(),"Due Today","Upcoming"))))) -> Not Scheduled | AA13: =IF($A13="","",IFERROR($Y13*$Z13,0)) -> 0 | AE13: =IF($B13="","",DATE(YEAR($B13),MONTH($B13),1)) -> 46235 | AF13: =IF($AB13="","",DATE(YEAR($AB13),MONTH($AB13),1)) | AG13: =IF($A13="","",IF(OR($Q13="Converted",$Q13="Closed",$Q13="Lost"),"No","Yes")) -> Yes | AH13: =IF($A13="","",IF($Q13="Converted","Yes","No")) -> No | AI13: =IF($A13="","",IF(OR($U13="Overdue",$U13="Due Today"),"Yes","No")) -> No
A14: 9 | B14: 46264 | C14: Udgam | D14: Mayur Joshi | E14: 9427380788 | G14: Ahmedabad | H14: India | I14: India | J14: Service | K14: NGO & Foundation | L14: Foundation | N14: Cold Outreach | O14: Aastha | P14: Hot | Q14: Converted | R14: Follow-Up Complete | S14: 46254 | U14: =IF($A14="","",IF(OR($Q14="Converted",$Q14="Closed",$Q14="Lost"),"Completed",IF($T14="","Not Scheduled",IF($T14<TODAY(),"Overdue",IF($T14=TODAY(),"Due Today","Upcoming"))))) -> Completed | AA14: =IF($A14="","",IFERROR($Y14*$Z14,0)) -> 0 | AE14: =IF($B14="","",DATE(YEAR($B14),MONTH($B14),1)) -> 46235 | AF14: =IF($AB14="","",DATE(YEAR($AB14),MONTH($AB14),1)) | AG14: =IF($A14="","",IF(OR($Q14="Converted",$Q14="Closed",$Q14="Lost"),"No","Yes")) -> No | AH14: =IF($A14="","",IF($Q14="Converted","Yes","No")) -> Yes | AI14: =IF($A14="","",IF(OR($U14="Overdue",$U14="Due Today"),"Yes","No")) -> No
A15: 10 | B15: 46264 | C15: Priyanshi/Home Inventory | D15: Chirag Kayastha House Manager | E15: 9727708384 | G15: Ahmedabad | H15: India | I15: India | J15: Service | K15: Other Services | L15: General Services | N15: Referral | O15: Aastha | P15: Hot | Q15: Demo/Meeting | R15: 3rd Follow-Up | S15: 46272 | U15: =IF($A15="","",IF(OR($Q15="Converted",$Q15="Closed",$Q15="Lost"),"Completed",IF($T15="","Not Scheduled",IF($T15<TODAY(),"Overdue",IF($T15=TODAY(),"Due Today","Upcoming"))))) -> Not Scheduled | AA15: =IF($A15="","",IFERROR($Y15*$Z15,0)) -> 0 | AE15: =IF($B15="","",DATE(YEAR($B15),MONTH($B15),1)) -> 46235 | AF15: =IF($AB15="","",DATE(YEAR($AB15),MONTH($AB15),1)) | AG15: =IF($A15="","",IF(OR($Q15="Converted",$Q15="Closed",$Q15="Lost"),"No","Yes")) -> Yes | AH15: =IF($A15="","",IF($Q15="Converted","Yes","No")) -> No | AI15: =IF($A15="","",IF(OR($U15="Overdue",$U15="Due Today"),"Yes","No")) -> No
A16: 11 | B16: 46264 | C16: Anison Pharmatech | D16: Anis husain | E16: 9499646116 | G16: Ahmedabad | H16: India | I16: India | J16: Service | K16: Healthcare | L16: Other Healthcare | N16: Event/Expo | O16: Aastha | P16: Medium | Q16: Qualified | R16: Follow-Up Complete | S16: 46264 | U16: =IF($A16="","",IF(OR($Q16="Converted",$Q16="Closed",$Q16="Lost"),"Completed",IF($T16="","Not Scheduled",IF($T16<TODAY(),"Overdue",IF($T16=TODAY(),"Due Today","Upcoming"))))) -> Not Scheduled | AA16: =IF($A16="","",IFERROR($Y16*$Z16,0)) -> 0 | AE16: =IF($B16="","",DATE(YEAR($B16),MONTH($B16),1)) -> 46235 | AF16: =IF($AB16="","",DATE(YEAR($AB16),MONTH($AB16),1)) | AG16: =IF($A16="","",IF(OR($Q16="Converted",$Q16="Closed",$Q16="Lost"),"No","Yes")) -> Yes | AH16: =IF($A16="","",IF($Q16="Converted","Yes","No")) -> No | AI16: =IF($A16="","",IF(OR($U16="Overdue",$U16="Due Today"),"Yes","No")) -> No
A17: 14 | B17: 46264 | C17: Bipin (Brother Spice Import Export) | D17: Bipin | E17: 8320404750 | G17: Ahmedabad | H17: India | I17: India | J17: Service | K17: Other Services | L17: General Services | N17: Event/Expo | O17: Aastha | P17: Medium | Q17: Contacted | R17: Follow-Up Complete | S17: 46261 | U17: =IF($A17="","",IF(OR($Q17="Converted",$Q17="Closed",$Q17="Lost"),"Completed",IF($T17="","Not Scheduled",IF($T17<TODAY(),"Overdue",IF($T17=TODAY(),"Due Today","Upcoming"))))) -> Not Scheduled | AA17: =IF($A17="","",IFERROR($Y17*$Z17,0)) -> 0 | AE17: =IF($B17="","",DATE(YEAR($B17),MONTH($B17),1)) -> 46235 | AF17: =IF($AB17="","",DATE(YEAR($AB17),MONTH($AB17),1)) | AG17: =IF($A17="","",IF(OR($Q17="Converted",$Q17="Closed",$Q17="Lost"),"No","Yes")) -> Yes | AH17: =IF($A17="","",IF($Q17="Converted","Yes","No")) -> No | AI17: =IF($A17="","",IF(OR($U17="Overdue",$U17="Due Today"),"Yes","No")) -> No
A18: 16 | B18: 46264 | C18: Abad Healthcare | D18: Heeram Ladhwala | E18: 9106868413 | G18: Ahmedabad | H18: India | I18: India | J18: Service | K18: Healthcare | L18: Other Healthcare | N18: Event/Expo | O18: Aastha | P18: Hot | Q18: Demo/Meeting | R18: 2nd Follow-Up | S18: 46265 | U18: =IF($A18="","",IF(OR($Q18="Converted",$Q18="Closed",$Q18="Lost"),"Completed",IF($T18="","Not Scheduled",IF($T18<TODAY(),"Overdue",IF($T18=TODAY(),"Due Today","Upcoming"))))) -> Not Scheduled | AA18: =IF($A18="","",IFERROR($Y18*$Z18,0)) -> 0 | AE18: =IF($B18="","",DATE(YEAR($B18),MONTH($B18),1)) -> 46235 | AF18: =IF($AB18="","",DATE(YEAR($AB18),MONTH($AB18),1)) | AG18: =IF($A18="","",IF(OR($Q18="Converted",$Q18="Closed",$Q18="Lost"),"No","Yes")) -> Yes | AH18: =IF($A18="","",IF($Q18="Converted","Yes","No")) -> No | AI18: =IF($A18="","",IF(OR($U18="Overdue",$U18="Due Today"),"Yes","No")) -> No
A19: 17 | B19: 46264 | C19: Divine Secret Pharma | D19: Mayur Solanki | E19: 9054070890 | G19: Ahmedabad | H19: India | I19: India | J19: Service | K19: Healthcare | L19: Other Healthcare | N19: Event/Expo | O19: Aastha | P19: Cold | Q19: New | R19: Not Started | U19: =IF($A19="","",IF(OR($Q19="Converted",$Q19="Closed",$Q19="Lost"),"Completed",IF($T19="","Not Scheduled",IF($T19<TODAY(),"Overdue",IF($T19=TODAY(),"Due Today","Upcoming"))))) -> Not Scheduled | AA19: =IF($A19="","",IFERROR($Y19*$Z19,0)) -> 0 | AE19: =IF($B19="","",DATE(YEAR($B19),MONTH($B19),1)) -> 46235 | AF19: =IF($AB19="","",DATE(YEAR($AB19),MONTH($AB19),1)) | AG19: =IF($A19="","",IF(OR($Q19="Converted",$Q19="Closed",$Q19="Lost"),"No","Yes")) -> Yes | AH19: =IF($A19="","",IF($Q19="Converted","Yes","No")) -> No | AI19: =IF($A19="","",IF(OR($U19="Overdue",$U19="Due Today"),"Yes","No")) -> No
A20: 18 | B20: 46264 | C20: Jigneshkumar | D20: Jigneshkumar | E20: 9428081191 | G20: Ahmedabad | H20: India | I20: India | J20: Service | K20: Healthcare | L20: Other Healthcare | N20: Event/Expo | O20: Aastha | P20: Hot | Q20: Contacted | R20: Initial Contact | S20: 46269 | U20: =IF($A20="","",IF(OR($Q20="Converted",$Q20="Closed",$Q20="Lost"),"Completed",IF($T20="","Not Scheduled",IF($T20<TODAY(),"Overdue",IF($T20=TODAY(),"Due Today","Upcoming"))))) -> Not Scheduled | AA20: =IF($A20="","",IFERROR($Y20*$Z20,0)) -> 0 | AE20: =IF($B20="","",DATE(YEAR($B20),MONTH($B20),1)) -> 46235 | AF20: =IF($AB20="","",DATE(YEAR($AB20),MONTH($AB20),1)) | AG20: =IF($A20="","",IF(OR($Q20="Converted",$Q20="Closed",$Q20="Lost"),"No","Yes")) -> Yes | AH20: =IF($A20="","",IF($Q20="Converted","Yes","No")) -> No | AI20: =IF($A20="","",IF(OR($U20="Overdue",$U20="Due Today"),"Yes","No")) -> No
A21: 20 | B21: 46264 | C21: Bhagat Pharmatech | D21: Manoj VNSGU | E21: 9723526717 / 9023424674 | G21: Ahmedabad | H21: India | I21: India | J21: Service | K21: Healthcare | L21: Other Healthcare | N21: Event/Expo | O21: Aastha | P21: Cold | Q21: New | R21: Not Started | U21: =IF($A21="","",IF(OR($Q21="Converted",$Q21="Closed",$Q21="Lost"),"Completed",IF($T21="","Not Scheduled",IF($T21<TODAY(),"Overdue",IF($T21=TODAY(),"Due Today","Upcoming"))))) -> Not Scheduled | AA21: =IF($A21="","",IFERROR($Y21*$Z21,0)) -> 0 | AE21: =IF($B21="","",DATE(YEAR($B21),MONTH($B21),1)) -> 46235 | AF21: =IF($AB21="","",DATE(YEAR($AB21),MONTH($AB21),1)) | AG21: =IF($A21="","",IF(OR($Q21="Converted",$Q21="Closed",$Q21="Lost"),"No","Yes")) -> Yes | AH21: =IF($A21="","",IF($Q21="Converted","Yes","No")) -> No | AI21: =IF($A21="","",IF(OR($U21="Overdue",$U21="Due Today"),"Yes","No")) -> No
A22: 21 | B22: 46264 | C22: Neo India Lifeline | D22: Khevna Maniar | E22: 9898107362 | G22: Ahmedabad | H22: India | I22: India | J22: Service | K22: Healthcare | L22: Other Healthcare | N22: Event/Expo | O22: Aastha | P22: Hot | Q22: Qualified | R22: 2nd Follow-Up | S22: 46272 | U22: =IF($A22="","",IF(OR($Q22="Converted",$Q22="Closed",$Q22="Lost"),"Completed",IF($T22="","Not Scheduled",IF($T22<TODAY(),"Overdue",IF($T22=TODAY(),"Due Today","Upcoming"))))) -> Not Scheduled | AA22: =IF($A22="","",IFERROR($Y22*$Z22,0)) -> 0 | AE22: =IF($B22="","",DATE(YEAR($B22),MONTH($B22),1)) -> 46235 | AF22: =IF($AB22="","",DATE(YEAR($AB22),MONTH($AB22),1)) | AG22: =IF($A22="","",IF(OR($Q22="Converted",$Q22="Closed",$Q22="Lost"),"No","Yes")) -> Yes | AH22: =IF($A22="","",IF($Q22="Converted","Yes","No")) -> No | AI22: =IF($A22="","",IF(OR($U22="Overdue",$U22="Due Today"),"Yes","No")) -> No
A23: 22 | B23: 46264 | C23: Chapter 1 | D23: Ankit Mandal | E23: 8530465246 | F23: hello@chapter1.finance | G23: Surat | H23: India | I23: India | J23: Service | K23: Healthcare | L23: Other Healthcare | N23: Event/Expo | O23: Aastha | P23: Cold | Q23: Lost | R23: Initial Contact | S23: 46269 | U23: =IF($A23="","",IF(OR($Q23="Converted",$Q23="Closed",$Q23="Lost"),"Completed",IF($T23="","Not Scheduled",IF($T23<TODAY(),"Overdue",IF($T23=TODAY(),"Due Today","Upcoming"))))) -> Completed | AA23: =IF($A23="","",IFERROR($Y23*$Z23,0)) -> 0 | AE23: =IF($B23="","",DATE(YEAR($B23),MONTH($B23),1)) -> 46235 | AF23: =IF($AB23="","",DATE(YEAR($AB23),MONTH($AB23),1)) | AG23: =IF($A23="","",IF(OR($Q23="Converted",$Q23="Closed",$Q23="Lost"),"No","Yes")) -> No | AH23: =IF($A23="","",IF($Q23="Converted","Yes","No")) -> No | AI23: =IF($A23="","",IF(OR($U23="Overdue",$U23="Due Today"),"Yes","No")) -> No
A24: 23 | B24: 46264 | C24: Raj Polymer | D24: Vipin Tiwari | E24: 9945185088 / 8970350803 | F24: vipin@rajploymer.com rajpolymer00@gmail.com | G24: Chikka Gollarahatti Bengaluru, Karnataka | H24: India | I24: India | J24: Service | K24: Healthcare | L24: Other Healthcare | N24: Event/Expo | O24: Aastha | P24: Cold | Q24: New | R24: Not Started | U24: =IF($A24="","",IF(OR($Q24="Converted",$Q24="Closed",$Q24="Lost"),"Completed",IF($T24="","Not Scheduled",IF($T24<TODAY(),"Overdue",IF($T24=TODAY(),"Due Today","Upcoming"))))) -> Not Scheduled | AA24: =IF($A24="","",IFERROR($Y24*$Z24,0)) -> 0 | AE24: =IF($B24="","",DATE(YEAR($B24),MONTH($B24),1)) -> 46235 | AF24: =IF($AB24="","",DATE(YEAR($AB24),MONTH($AB24),1)) | AG24: =IF($A24="","",IF(OR($Q24="Converted",$Q24="Closed",$Q24="Lost"),"No","Yes")) -> Yes | AH24: =IF($A24="","",IF($Q24="Converted","Yes","No")) -> No | AI24: =IF($A24="","",IF(OR($U24="Overdue",$U24="Due Today"),"Yes","No")) -> No
A25: 24 | B25: 46264 | C25: Novatoz Scientific LLP | D25: Sandip Patel | E25: 9724330701 | F25: info.novatoz@gmail.com | G25: Ahmedabad | H25: India | I25: India | J25: Service | K25: Healthcare | L25: Other Healthcare | N25: Event/Expo | O25: Aastha | P25: Cold | Q25: New | R25: Not Started | U25: =IF($A25="","",IF(OR($Q25="Converted",$Q25="Closed",$Q25="Lost"),"Completed",IF($T25="","Not Scheduled",IF($T25<TODAY(),"Overdue",IF($T25=TODAY(),"Due Today","Upcoming"))))) -> Not Scheduled | AA25: =IF($A25="","",IFERROR($Y25*$Z25,0)) -> 0 | AE25: =IF($B25="","",DATE(YEAR($B25),MONTH($B25),1)) -> 46235 | AF25: =IF($AB25="","",DATE(YEAR($AB25),MONTH($AB25),1)) | AG25: =IF($A25="","",IF(OR($Q25="Converted",$Q25="Closed",$Q25="Lost"),"No","Yes")) -> Yes | AH25: =IF($A25="","",IF($Q25="Converted","Yes","No")) -> No | AI25: =IF($A25="","",IF(OR($U25="Overdue",$U25="Due Today"),"Yes","No")) -> No
A26: 25 | B26: 46264 | C26: Sheel Overseas | D26: Sheel Shah | E26: 9586855566 | F26: info@sheelloverseas.com | G26: Ahmedabad | H26: India | I26: India | J26: Service | K26: Other Services | L26: Manufacturing | N26: Event/Expo | O26: Aastha | P26: Cold | Q26: New | R26: Not Started | U26: =IF($A26="","",IF(OR($Q26="Converted",$Q26="Closed",$Q26="Lost"),"Completed",IF($T26="","Not Scheduled",IF($T26<TODAY(),"Overdue",IF($T26=TODAY(),"Due Today","Upcoming"))))) -> Not Scheduled | AA26: =IF($A26="","",IFERROR($Y26*$Z26,0)) -> 0 | AE26: =IF($B26="","",DATE(YEAR($B26),MONTH($B26),1)) -> 46235 | AF26: =IF($AB26="","",DATE(YEAR($AB26),MONTH($AB26),1)) | AG26: =IF($A26="","",IF(OR($Q26="Converted",$Q26="Closed",$Q26="Lost"),"No","Yes")) -> Yes | AH26: =IF($A26="","",IF($Q26="Converted","Yes","No")) -> No | AI26: =IF($A26="","",IF(OR($U26="Overdue",$U26="Due Today"),"Yes","No")) -> No
A27: 26 | B27: 46264 | C27: Shamura Polytech PVT. Ltd | D27: Rajesh Rami (Marketing Manager) | E27: 9913864345; 902325424 | F27: shamurapolytechpvt.ltd@gmail.com | G27: Vijapur | H27: India | I27: India | J27: Service | K27: Manufacturing | L27: Manufacturing | N27: Event/Expo | O27: Aastha | P27: Cold | Q27: New | R27: Not Started | U27: =IF($A27="","",IF(OR($Q27="Converted",$Q27="Closed",$Q27="Lost"),"Completed",IF($T27="","Not Scheduled",IF($T27<TODAY(),"Overdue",IF($T27=TODAY(),"Due Today","Upcoming"))))) -> Not Scheduled | AA27: =IF($A27="","",IFERROR($Y27*$Z27,0)) -> 0 | AE27: =IF($B27="","",DATE(YEAR($B27),MONTH($B27),1)) -> 46235 | AF27: =IF($AB27="","",DATE(YEAR($AB27),MONTH($AB27),1)) | AG27: =IF($A27="","",IF(OR($Q27="Converted",$Q27="Closed",$Q27="Lost"),"No","Yes")) -> Yes | AH27: =IF($A27="","",IF($Q27="Converted","Yes","No")) -> No | AI27: =IF($A27="","",IF(OR($U27="Overdue",$U27="Due Today"),"Yes","No")) -> No
A28: 27 | B28: 46264 | C28: Marengo CIMS Hospital / Marengo Asia Healthcare Private Limited | D28: Dr Bhagyesh Shah | E28: 9099068938 | F28: bhagyesh.shah@marengoasia.com; marengocims.opd.rec@marengoasia.com | G28: Ahmedabad | H28: India | I28: India | J28: Service | K28: Healthcare | L28: Other Healthcare | N28: Event/Expo | O28: Aastha | P28: Cold | Q28: New | R28: Not Started | U28: =IF($A28="","",IF(OR($Q28="Converted",$Q28="Closed",$Q28="Lost"),"Completed",IF($T28="","Not Scheduled",IF($T28<TODAY(),"Overdue",IF($T28=TODAY(),"Due Today","Upcoming"))))) -> Not Scheduled | AA28: =IF($A28="","",IFERROR($Y28*$Z28,0)) -> 0 | AE28: =IF($B28="","",DATE(YEAR($B28),MONTH($B28),1)) -> 46235 | AF28: =IF($AB28="","",DATE(YEAR($AB28),MONTH($AB28),1)) | AG28: =IF($A28="","",IF(OR($Q28="Converted",$Q28="Closed",$Q28="Lost"),"No","Yes")) -> Yes | AH28: =IF($A28="","",IF($Q28="Converted","Yes","No")) -> No | AI28: =IF($A28="","",IF(OR($U28="Overdue",$U28="Due Today"),"Yes","No")) -> No
A29: 28 | B29: 46264 | C29: Enervia Nutraceuticals Private Limited | D29: Sachin Thakkar (Director) | E29: 9925044953 | F29: sachin.thakkar@enervia.in | G29: Ahmedabad | H29: India | I29: India | J29: Service | K29: Healthcare | L29: Other Healthcare | N29: Event/Expo | O29: Aastha | P29: Cold | Q29: New | R29: Not Started | U29: =IF($A29="","",IF(OR($Q29="Converted",$Q29="Closed",$Q29="Lost"),"Completed",IF($T29="","Not Scheduled",IF($T29<TODAY(),"Overdue",IF($T29=TODAY(),"Due Today","Upcoming"))))) -> Not Scheduled | AA29: =IF($A29="","",IFERROR($Y29*$Z29,0)) -> 0 | AE29: =IF($B29="","",DATE(YEAR($B29),MONTH($B29),1)) -> 46235 | AF29: =IF($AB29="","",DATE(YEAR($AB29),MONTH($AB29),1)) | AG29: =IF($A29="","",IF(OR($Q29="Converted",$Q29="Closed",$Q29="Lost"),"No","Yes")) -> Yes | AH29: =IF($A29="","",IF($Q29="Converted","Yes","No")) -> No | AI29: =IF($A29="","",IF(OR($U29="Overdue",$U29="Due Today"),"Yes","No")) -> No
A30: 29 | B30: 46264 | C30: Vishva World | D30: Jigaa Kapadia (Global Network Connector) | E30: 7570788686 | F30: info@vishva.world | H30: India | I30: India | J30: Service | K30: Other Services | L30: General Services | N30: Event/Expo | O30: Aastha | P30: Cold | Q30: New | R30: Not Started | U30: =IF($A30="","",IF(OR($Q30="Converted",$Q30="Closed",$Q30="Lost"),"Completed",IF($T30="","Not Scheduled",IF($T30<TODAY(),"Overdue",IF($T30=TODAY(),"Due Today","Upcoming"))))) -> Not Scheduled | AA30: =IF($A30="","",IFERROR($Y30*$Z30,0)) -> 0 | AE30: =IF($B30="","",DATE(YEAR($B30),MONTH($B30),1)) -> 46235 | AF30: =IF($AB30="","",DATE(YEAR($AB30),MONTH($AB30),1)) | AG30: =IF($A30="","",IF(OR($Q30="Converted",$Q30="Closed",$Q30="Lost"),"No","Yes")) -> Yes | AH30: =IF($A30="","",IF($Q30="Converted","Yes","No")) -> No | AI30: =IF($A30="","",IF(OR($U30="Overdue",$U30="Due Today"),"Yes","No")) -> No
A31: 30 | B31: 46264 | C31: Bizkey Consultancy | D31: Vani Mehta (Founder) | E31: 8980778631 | F31: vani.mehta@bizkey.biz | G31: Ahmedabad | H31: India | I31: India | J31: Service | K31: Other Products | L31: General Services | N31: Event/Expo | O31: Aastha | P31: Cold | Q31: New | R31: Not Started | U31: =IF($A31="","",IF(OR($Q31="Converted",$Q31="Closed",$Q31="Lost"),"Completed",IF($T31="","Not Scheduled",IF($T31<TODAY(),"Overdue",IF($T31=TODAY(),"Due Today","Upcoming"))))) -> Not Scheduled | AA31: =IF($A31="","",IFERROR($Y31*$Z31,0)) -> 0 | AE31: =IF($B31="","",DATE(YEAR($B31),MONTH($B31),1)) -> 46235 | AF31: =IF($AB31="","",DATE(YEAR($AB31),MONTH($AB31),1)) | AG31: =IF($A31="","",IF(OR($Q31="Converted",$Q31="Closed",$Q31="Lost"),"No","Yes")) -> Yes | AH31: =IF($A31="","",IF($Q31="Converted","Yes","No")) -> No | AI31: =IF($A31="","",IF(OR($U31="Overdue",$U31="Due Today"),"Yes","No")) -> No
A32: 31 | B32: 46264 | C32: Adfinmark Multisolution Pvt. Ltd. | D32: Chinmay H Mehta (Zone Director) | E32: 7600084422 | F32: chinmay@adfinmark.com | G32: Yamuna Nagar / Nagpur / Amritsar / Ahmedabad | H32: India | I32: India | J32: Service | K32: Other Products | L32: General Services | N32: Event/Expo | O32: Aastha | P32: Cold | Q32: New | R32: Not Started | U32: =IF($A32="","",IF(OR($Q32="Converted",$Q32="Closed",$Q32="Lost"),"Completed",IF($T32="","Not Scheduled",IF($T32<TODAY(),"Overdue",IF($T32=TODAY(),"Due Today","Upcoming"))))) -> Not Scheduled | AA32: =IF($A32="","",IFERROR($Y32*$Z32,0)) -> 0 | AE32: =IF($B32="","",DATE(YEAR($B32),MONTH($B32),1)) -> 46235 | AF32: =IF($AB32="","",DATE(YEAR($AB32),MONTH($AB32),1)) | AG32: =IF($A32="","",IF(OR($Q32="Converted",$Q32="Closed",$Q32="Lost"),"No","Yes")) -> Yes | AH32: =IF($A32="","",IF($Q32="Converted","Yes","No")) -> No | AI32: =IF($A32="","",IF(OR($U32="Overdue",$U32="Due Today"),"Yes","No")) -> No
A33: 32 | B33: 46264 | C33: D.N. Laser | D33: Dharmesh / Gaurang | E33: 9998100274; 9428671616 | F33: d.n.laser1996@gmail.com | G33: Ahmedabad | H33: India | I33: India | J33: Service | K33: Other Products | L33: General Services | N33: Event/Expo | O33: Aastha | P33: Cold | Q33: New | R33: Not Started | U33: =IF($A33="","",IF(OR($Q33="Converted",$Q33="Closed",$Q33="Lost"),"Completed",IF($T33="","Not Scheduled",IF($T33<TODAY(),"Overdue",IF($T33=TODAY(),"Due Today","Upcoming"))))) -> Not Scheduled | AA33: =IF($A33="","",IFERROR($Y33*$Z33,0)) -> 0 | AE33: =IF($B33="","",DATE(YEAR($B33),MONTH($B33),1)) -> 46235 | AF33: =IF($AB33="","",DATE(YEAR($AB33),MONTH($AB33),1)) | AG33: =IF($A33="","",IF(OR($Q33="Converted",$Q33="Closed",$Q33="Lost"),"No","Yes")) -> Yes | AH33: =IF($A33="","",IF($Q33="Converted","Yes","No")) -> No | AI33: =IF($A33="","",IF(OR($U33="Overdue",$U33="Due Today"),"Yes","No")) -> No
A34: 33 | B34: 46264 | C34: REIN ENTERPRISE | E34: 8511860282 | F34: reinenterprise3015@gmail.com | G34: Ahmedabad | H34: India | I34: India | J34: Service | K34: Other Services | L34: General Services | N34: Event/Expo | O34: Aastha | P34: Cold | Q34: New | R34: Not Started | U34: =IF($A34="","",IF(OR($Q34="Converted",$Q34="Closed",$Q34="Lost"),"Completed",IF($T34="","Not Scheduled",IF($T34<TODAY(),"Overdue",IF($T34=TODAY(),"Due Today","Upcoming"))))) -> Not Scheduled | AA34: =IF($A34="","",IFERROR($Y34*$Z34,0)) -> 0 | AE34: =IF($B34="","",DATE(YEAR($B34),MONTH($B34),1)) -> 46235 | AF34: =IF($AB34="","",DATE(YEAR($AB34),MONTH($AB34),1)) | AG34: =IF($A34="","",IF(OR($Q34="Converted",$Q34="Closed",$Q34="Lost"),"No","Yes")) -> Yes | AH34: =IF($A34="","",IF($Q34="Converted","Yes","No")) -> No | AI34: =IF($A34="","",IF(OR($U34="Overdue",$U34="Due Today"),"Yes","No")) -> No
A35: 34 | B35: 46264 | C35: SINGH ENTERPRISES | D35: Ekyot Singh | E35: 9619134047; 9820070228 | F35: singh_enterprises7@yahoo.com; info@singh-enterprises.com | G35: Mumbai | H35: India | I35: India | J35: Service | K35: Manufacturing | L35: Manufacturing | N35: Event/Expo | O35: Aastha | P35: Cold | Q35: New | R35: Not Started | U35: =IF($A35="","",IF(OR($Q35="Converted",$Q35="Closed",$Q35="Lost"),"Completed",IF($T35="","Not Scheduled",IF($T35<TODAY(),"Overdue",IF($T35=TODAY(),"Due Today","Upcoming"))))) -> Not Scheduled | AA35: =IF($A35="","",IFERROR($Y35*$Z35,0)) -> 0 | AE35: =IF($B35="","",DATE(YEAR($B35),MONTH($B35),1)) -> 46235 | AF35: =IF($AB35="","",DATE(YEAR($AB35),MONTH($AB35),1)) | AG35: =IF($A35="","",IF(OR($Q35="Converted",$Q35="Closed",$Q35="Lost"),"No","Yes")) -> Yes | AH35: =IF($A35="","",IF($Q35="Converted","Yes","No")) -> No | AI35: =IF($A35="","",IF(OR($U35="Overdue",$U35="Due Today"),"Yes","No")) -> No
A36: 35 | B36: 46264 | C36: DEV OPUS PVT. LTD. | D36: Akash Dabhi (Senior Business Development Executive) | E36: 8734010864 | F36: bade@devopus.com | G36: Ahmedabad | H36: India | I36: India | J36: Service | K36: Other Services | L36: General Services | N36: Event/Expo | O36: Aastha | P36: Cold | Q36: New | R36: Not Started | U36: =IF($A36="","",IF(OR($Q36="Converted",$Q36="Closed",$Q36="Lost"),"Completed",IF($T36="","Not Scheduled",IF($T36<TODAY(),"Overdue",IF($T36=TODAY(),"Due Today","Upcoming"))))) -> Not Scheduled | AA36: =IF($A36="","",IFERROR($Y36*$Z36,0)) -> 0 | AE36: =IF($B36="","",DATE(YEAR($B36),MONTH($B36),1)) -> 46235 | AF36: =IF($AB36="","",DATE(YEAR($AB36),MONTH($AB36),1)) | AG36: =IF($A36="","",IF(OR($Q36="Converted",$Q36="Closed",$Q36="Lost"),"No","Yes")) -> Yes | AH36: =IF($A36="","",IF($Q36="Converted","Yes","No")) -> No | AI36: =IF($A36="","",IF(OR($U36="Overdue",$U36="Due Today"),"Yes","No")) -> No
A37: 36 | B37: 46264 | C37: FLUID FLOW ENGINEERS | D37: Dingare Yogesh | E37: 9326204116 | F37: fluidflowengg20213@gmail.com | G37: Pune | H37: India | I37: India | J37: Service | K37: Other Services | L37: General Services | N37: Event/Expo | O37: Aastha | P37: Cold | Q37: New | R37: Not Started | U37: =IF($A37="","",IF(OR($Q37="Converted",$Q37="Closed",$Q37="Lost"),"Completed",IF($T37="","Not Scheduled",IF($T37<TODAY(),"Overdue",IF($T37=TODAY(),"Due Today","Upcoming"))))) -> Not Scheduled | AA37: =IF($A37="","",IFERROR($Y37*$Z37,0)) -> 0 | AE37: =IF($B37="","",DATE(YEAR($B37),MONTH($B37),1)) -> 46235 | AF37: =IF($AB37="","",DATE(YEAR($AB37),MONTH($AB37),1)) | AG37: =IF($A37="","",IF(OR($Q37="Converted",$Q37="Closed",$Q37="Lost"),"No","Yes")) -> Yes | AH37: =IF($A37="","",IF($Q37="Converted","Yes","No")) -> No | AI37: =IF($A37="","",IF(OR($U37="Overdue",$U37="Due Today"),"Yes","No")) -> No
A38: 37 | B38: 46264 | C38: Anax Lifescience Private Limited | D38: Samir Patel (Managing Director) | E38: 9879105608 | F38: info@anaxlifescience.in | G38: Ahmedabad | H38: India | I38: India | J38: Service | K38: Healthcare | L38: Pharma | N38: Event/Expo | O38: Aastha | P38: Cold | Q38: New | R38: Not Started | U38: =IF($A38="","",IF(OR($Q38="Converted",$Q38="Closed",$Q38="Lost"),"Completed",IF($T38="","Not Scheduled",IF($T38<TODAY(),"Overdue",IF($T38=TODAY(),"Due Today","Upcoming"))))) -> Not Scheduled | AA38: =IF($A38="","",IFERROR($Y38*$Z38,0)) -> 0 | AE38: =IF($B38="","",DATE(YEAR($B38),MONTH($B38),1)) -> 46235 | AF38: =IF($AB38="","",DATE(YEAR($AB38),MONTH($AB38),1)) | AG38: =IF($A38="","",IF(OR($Q38="Converted",$Q38="Closed",$Q38="Lost"),"No","Yes")) -> Yes | AH38: =IF($A38="","",IF($Q38="Converted","Yes","No")) -> No | AI38: =IF($A38="","",IF(OR($U38="Overdue",$U38="Due Today"),"Yes","No")) -> No
A39: 38 | B39: 46264 | C39: Sachdev Scientific Equipments / Blancoz | D39: Aditya Sachdev (Director) | E39: 90330 07000; 7721-290133 | F39: info@blancoz.in; sachdevaditya@hotmail.com | G39: Raipur | H39: India | I39: India | J39: Service | K39: Manufacturing | L39: Manufacturing | N39: Event/Expo | O39: Aastha | P39: Cold | Q39: New | R39: Not Started | U39: =IF($A39="","",IF(OR($Q39="Converted",$Q39="Closed",$Q39="Lost"),"Completed",IF($T39="","Not Scheduled",IF($T39<TODAY(),"Overdue",IF($T39=TODAY(),"Due Today","Upcoming"))))) -> Not Scheduled | AA39: =IF($A39="","",IFERROR($Y39*$Z39,0)) -> 0 | AE39: =IF($B39="","",DATE(YEAR($B39),MONTH($B39),1)) -> 46235 | AF39: =IF($AB39="","",DATE(YEAR($AB39),MONTH($AB39),1)) | AG39: =IF($A39="","",IF(OR($Q39="Converted",$Q39="Closed",$Q39="Lost"),"No","Yes")) -> Yes | AH39: =IF($A39="","",IF($Q39="Converted","Yes","No")) -> No | AI39: =IF($A39="","",IF(OR($U39="Overdue",$U39="Due Today"),"Yes","No")) -> No
A40: 39 | B40: 46264 | C40: Kalpana Lights / Seridone | D40: Vijaysingh Rajput / Arjunsingh Rajput | E40: 9773479961; 9930479535; 079 22155334 | G40: Ahmedabad | H40: India | I40: India | J40: Service | K40: Manufacturing | L40: Manufacturing | N40: Event/Expo | O40: Aastha | P40: Cold | Q40: New | R40: Not Started | U40: =IF($A40="","",IF(OR($Q40="Converted",$Q40="Closed",$Q40="Lost"),"Completed",IF($T40="","Not Scheduled",IF($T40<TODAY(),"Overdue",IF($T40=TODAY(),"Due Today","Upcoming"))))) -> Not Scheduled | AA40: =IF($A40="","",IFERROR($Y40*$Z40,0)) -> 0 | AE40: =IF($B40="","",DATE(YEAR($B40),MONTH($B40),1)) -> 46235 | AF40: =IF($AB40="","",DATE(YEAR($AB40),MONTH($AB40),1)) | AG40: =IF($A40="","",IF(OR($Q40="Converted",$Q40="Closed",$Q40="Lost"),"No","Yes")) -> Yes | AH40: =IF($A40="","",IF($Q40="Converted","Yes","No")) -> No | AI40: =IF($A40="","",IF(OR($U40="Overdue",$U40="Due Today"),"Yes","No")) -> No
A41: 40 | B41: 46264 | C41: CHL / Communities Heritage Limited | D41: Gaurav Kumar (Sales Head) | E41: 8209941243 | F41: ahmedabad@chlgroup.org | G41: Ahmedabad | H41: India | I41: India | J41: Service | K41: Other Services | L41: General Services | N41: Event/Expo | O41: Aastha | P41: Cold | Q41: New | R41: Not Started | U41: =IF($A41="","",IF(OR($Q41="Converted",$Q41="Closed",$Q41="Lost"),"Completed",IF($T41="","Not Scheduled",IF($T41<TODAY(),"Overdue",IF($T41=TODAY(),"Due Today","Upcoming"))))) -> Not Scheduled | AA41: =IF($A41="","",IFERROR($Y41*$Z41,0)) -> 0 | AE41: =IF($B41="","",DATE(YEAR($B41),MONTH($B41),1)) -> 46235 | AF41: =IF($AB41="","",DATE(YEAR($AB41),MONTH($AB41),1)) | AG41: =IF($A41="","",IF(OR($Q41="Converted",$Q41="Closed",$Q41="Lost"),"No","Yes")) -> Yes | AH41: =IF($A41="","",IF($Q41="Converted","Yes","No")) -> No | AI41: =IF($A41="","",IF(OR($U41="Overdue",$U41="Due Today"),"Yes","No")) -> No
...

Sheet Dashboard
A1: TechSentinals CRM Dashboard
A2: Overall funnel, India vs Foreign performance, pipeline value, conversions, and daily follow-up health.
A4: Total Leads | B4: =COUNTIF('Master Leads'!$A$6:$A$495,"<>") -> 121 | D4: Open Leads | E4: =COUNTIFS('Master Leads'!$A$6:$A$495,"<>",'Master Leads'!$AG$6:$AG$495,"Yes") -> 112 | G4: Converted | H4: =COUNTIFS('Master Leads'!$A$6:$A$495,"<>",'Master Leads'!$Q$6:$Q$495,"Converted") -> 5 | J4: Conversion Rate | K4: =IFERROR($H$4/$B$4,0) -> 0.041322314
A7: Open Pipeline | B7: =SUMIFS('Master Leads'!$Y$6:$Y$495,'Master Leads'!$A$6:$A$495,"<>",'Master Leads'!$AG$6:$AG$495,"Yes") -> 0 | D7: Weighted Pipeline | E7: =SUMIFS('Master Leads'!$AA$6:$AA$495,'Master Leads'!$A$6:$A$495,"<>",'Master Leads'!$AG$6:$AG$495,"Yes") -> 0 | G7: Due Today | H7: =COUNTIFS('Master Leads'!$A$6:$A$495,"<>",'Master Leads'!$U$6:$U$495,"Due Today") -> 0 | J7: Overdue | K7: =COUNTIFS('Master Leads'!$A$6:$A$495,"<>",'Master Leads'!$U$6:$U$495,"Overdue") -> 0
A10: India Leads | B10: =COUNTIFS('Master Leads'!$A$6:$A$495,"<>",'Master Leads'!$I$6:$I$495,"India") -> 112 | D10: Foreign Leads | E10: =COUNTIFS('Master Leads'!$A$6:$A$495,"<>",'Master Leads'!$I$6:$I$495,"Foreign") -> 8 | G10: India Converted | H10: =COUNTIFS('Master Leads'!$A$6:$A$495,"<>",'Master Leads'!$I$6:$I$495,"India",'Master Leads'!$Q$6:$Q$495,"Converted") -> 5 | J10: Foreign Converted | K10: =COUNTIFS('Master Leads'!$A$6:$A$495,"<>",'Master Leads'!$I$6:$I$495,"Foreign",'Master Leads'!$Q$6:$Q$495,"Converted") -> 0
A32: Priority colors: Hot = urgent, Medium = active, Cold = nurture. Follow-up colors: red = overdue, amber = due today, green = upcoming.

Sheet Contact Log
A1: Contact Log — Optional Detailed History
A2: Use one row for each call, WhatsApp, email, meeting, demo, proposal, visit, or other contact. Company and owner are filled from the Lead ID.
A5: Activity ID | B5: Contact Date | C5: Lead ID | D5: Company / Person | E5: Contact Type | F5: Follow-Up Round | G5: Outcome | H5: Next Follow-Up Date | I5: Assigned To | J5: Notes
D6: {=IF($C6="","",IFERROR(INDEX('Master Leads'!$C$6:$C$495,MATCH($C6,'Master Leads'!$A$6:$A$495,0)),""))} | E6: Call | F6: Initial | I6: {=IF($C6="","",IFERROR(INDEX('Master Leads'!$O$6:$O$495,MATCH($C6,'Master Leads'!$A$6:$A$495,0)),""))}
D7: {=IF($C7="","",IFERROR(INDEX('Master Leads'!$C$6:$C$495,MATCH($C7,'Master Leads'!$A$6:$A$495,0)),""))} | I7: {=IF($C7="","",IFERROR(INDEX('Master Leads'!$O$6:$O$495,MATCH($C7,'Master Leads'!$A$6:$A$495,0)),""))}
D8: {=IF($C8="","",IFERROR(INDEX('Master Leads'!$C$6:$C$495,MATCH($C8,'Master Leads'!$A$6:$A$495,0)),""))} | I8: {=IF($C8="","",IFERROR(INDEX('Master Leads'!$O$6:$O$495,MATCH($C8,'Master Leads'!$A$6:$A$495,0)),""))}
D9: {=IF($C9="","",IFERROR(INDEX('Master Leads'!$C$6:$C$495,MATCH($C9,'Master Leads'!$A$6:$A$495,0)),""))} | I9: {=IF($C9="","",IFERROR(INDEX('Master Leads'!$O$6:$O$495,MATCH($C9,'Master Leads'!$A$6:$A$495,0)),""))}
D10: {=IF($C10="","",IFERROR(INDEX('Master Leads'!$C$6:$C$495,MATCH($C10,'Master Leads'!$A$6:$A$495,0)),""))} | I10: {=IF($C10="","",IFERROR(INDEX('Master Leads'!$O$6:$O$495,MATCH($C10,'Master Leads'!$A$6:$A$495,0)),""))}
D11: {=IF($C11="","",IFERROR(INDEX('Master Leads'!$C$6:$C$495,MATCH($C11,'Master Leads'!$A$6:$A$495,0)),""))} | I11: {=IF($C11="","",IFERROR(INDEX('Master Leads'!$O$6:$O$495,MATCH($C11,'Master Leads'!$A$6:$A$495,0)),""))}
D12: {=IF($C12="","",IFERROR(INDEX('Master Leads'!$C$6:$C$495,MATCH($C12,'Master Leads'!$A$6:$A$495,0)),""))} | I12: {=IF($C12="","",IFERROR(INDEX('Master Leads'!$O$6:$O$495,MATCH($C12,'Master Leads'!$A$6:$A$495,0)),""))}
D13: {=IF($C13="","",IFERROR(INDEX('Master Leads'!$C$6:$C$495,MATCH($C13,'Master Leads'!$A$6:$A$495,0)),""))} | I13: {=IF($C13="","",IFERROR(INDEX('Master Leads'!$O$6:$O$495,MATCH($C13,'Master Leads'!$A$6:$A$495,0)),""))}
D14: {=IF($C14="","",IFERROR(INDEX('Master Leads'!$C$6:$C$495,MATCH($C14,'Master Leads'!$A$6:$A$495,0)),""))} | I14: {=IF($C14="","",IFERROR(INDEX('Master Leads'!$O$6:$O$495,MATCH($C14,'Master Leads'!$A$6:$A$495,0)),""))}
D15: {=IF($C15="","",IFERROR(INDEX('Master Leads'!$C$6:$C$495,MATCH($C15,'Master Leads'!$A$6:$A$495,0)),""))} | I15: {=IF($C15="","",IFERROR(INDEX('Master Leads'!$O$6:$O$495,MATCH($C15,'Master Leads'!$A$6:$A$495,0)),""))}
D16: {=IF($C16="","",IFERROR(INDEX('Master Leads'!$C$6:$C$495,MATCH($C16,'Master Leads'!$A$6:$A$495,0)),""))} | I16: {=IF($C16="","",IFERROR(INDEX('Master Leads'!$O$6:$O$495,MATCH($C16,'Master Leads'!$A$6:$A$495,0)),""))}
D17: {=IF($C17="","",IFERROR(INDEX('Master Leads'!$C$6:$C$495,MATCH($C17,'Master Leads'!$A$6:$A$495,0)),""))} | I17: {=IF($C17="","",IFERROR(INDEX('Master Leads'!$O$6:$O$495,MATCH($C17,'Master Leads'!$A$6:$A$495,0)),""))}
D18: {=IF($C18="","",IFERROR(INDEX('Master Leads'!$C$6:$C$495,MATCH($C18,'Master Leads'!$A$6:$A$495,0)),""))} | I18: {=IF($C18="","",IFERROR(INDEX('Master Leads'!$O$6:$O$495,MATCH($C18,'Master Leads'!$A$6:$A$495,0)),""))}
... D505: {=IF($C505="","",IFERROR(INDEX('Master Leads'!$C$6:$C$495,MATCH($C505,'Master Leads'!$A$6:$A$495,0)),""))} | I505: {=IF($C505="","",IFERROR(INDEX('Master Leads'!$O$6:$O$495,MATCH($C505,'Master Leads'!$A$6:$A$495,0)),""))}

Sheet Follow Ups
A1: Follow-Ups — Daily Action Queue
A2: Open this tab each day. The table lists every open lead with a scheduled follow-up, sorted by Next Follow-Up Date.
A3: Due Today | B3: =COUNTIFS('Master Leads'!$A$6:$A$495,"<>",'Master Leads'!$U$6:$U$495,"Due Today") -> 0 | D3: Overdue | E3: =COUNTIFS('Master Leads'!$A$6:$A$495,"<>",'Master Leads'!$U$6:$U$495,"Overdue") -> 0 | G3: Next 7 Days | H3: =COUNTIFS('Master Leads'!$A$6:$A$495,"<>",'Master Leads'!$AG$6:$AG$495,"Yes",'Master Leads'!$T$6:$T$495,">"&TODAY(),'Master Leads'!$T$6:$T$495,"<="&TODAY()+7) -> 0 | J3: No Date | K3: =COUNTIFS('Master Leads'!$A$6:$A$495,"<>",'Master Leads'!$AG$6:$AG$495,"Yes",'Master Leads'!$T$6:$T$495,"") -> 112
A5: Lead ID | B5: Date Added | C5: Company / Person | D5: Contact Person | E5: Phone / WhatsApp | F5: Email | G5: City | H5: Country | I5: Market | J5: Business Side | K5: Department / Product | L5: Category | M5: Requirement / Interested In | N5: Lead Source | O5: Assigned To | P5: Priority | Q5: Sales Stage | R5: Follow-Up Round | S5: Last Contact Date | T5: Next Follow-Up Date | U5: Follow-Up Status | V5: Next Action
A6: =IFERROR(__xludf.DUMMYFUNCTION("IFERROR(SORT(FILTER('Master Leads'!$A$6:$V$495, 'Master Leads'!$A$6:$A$495<>"""", 'Master Leads'!$AG$6:$AG$495=""Yes"", 'Master Leads'!$T$6:$T$495<>""""), 20, 1), ""No open follow-ups scheduled"")"),"No open follow-ups scheduled") -> No open follow-ups scheduled

Sheet Healthcare - Pharma
A1: Healthcare / Pharma Leads
A2: Read-only view from Master Leads. Add and update records in Master Leads so all reporting stays synchronized.
A5: Lead ID | B5: Date Added | C5: Company / Person | D5: Contact Person | E5: Phone / WhatsApp | F5: Email | G5: City | H5: Country | I5: Market | J5: Business Side | K5: Department / Product | L5: Category | M5: Requirement / Interested In | N5: Lead Source | O5: Assigned To | P5: Priority | Q5: Sales Stage | R5: Follow-Up Round | S5: Last Contact Date | T5: Next Follow-Up Date | U5: Follow-Up Status | V5: Next Action | W5: Meeting / Demo Date | X5: Proposal Date | Y5: Deal Value (INR) | Z5: Probability | AA5: Weighted Pipeline | AB5: Conversion / Close Date | AC5: Lost / Closed Reason | AD5: Notes
A6: =IFERROR(__xludf.DUMMYFUNCTION("IFERROR(FILTER('Master Leads'!$A$6:$AD$495, 'Master Leads'!$A$6:$A$495<>"""", 'Master Leads'!$K$6:$K$495=""Healthcare"", 'Master Leads'!$L$6:$L$495=""Pharma""), ""No matching leads yet"")"),1.0) -> 1 | B6: =IFERROR(__xludf.DUMMYFUNCTION("""COMPUTED_VALUE"""),46264.0) -> 46264 | C6: =IFERROR(__xludf.DUMMYFUNCTION("""COMPUTED_VALUE"""),"Inventa") -> Inventa | D6: =IFERROR(__xludf.DUMMYFUNCTION("""COMPUTED_VALUE"""),"Darshit") -> Darshit | E6: =IFERROR(__xludf.DUMMYFUNCTION("""COMPUTED_VALUE"""),"7285043792") -> 7285043792 | F6: =IFERROR(__xludf.DUMMYFUNCTION("""COMPUTED_VALUE"""),"inventasys@gmail.com") -> inventasys@gmail.com | G6: =IFERROR(__xludf.DUMMYFUNCTION("""COMPUTED_VALUE"""),"Ahmedabad") -> Ahmedabad | H6: =IFERROR(__xludf.DUMMYFUNCTION("""COMPUTED_VALUE"""),"India") -> India | I6: =IFERROR(__xludf.DUMMYFUNCTION("""COMPUTED_VALUE"""),"India") -> India | J6: =IFERROR(__xludf.DUMMYFUNCTION("""COMPUTED_VALUE"""),"Service") -> Service | K6: =IFERROR(__xludf.DUMMYFUNCTION("""COMPUTED_VALUE"""),"Healthcare") -> Healthcare | L6: =IFERROR(__xludf.DUMMYFUNCTION("""COMPUTED_VALUE"""),"Pharma") -> Pharma | N6: =IFERROR(__xludf.DUMMYFUNCTION("""COMPUTED_VALUE"""),"Event/Expo") -> Event/Expo | O6: =IFERROR(__xludf.DUMMYFUNCTION("""COMPUTED_VALUE"""),"Aastha") -> Aastha | P6: =IFERROR(__xludf.DUMMYFUNCTION("""COMPUTED_VALUE"""),"Medium") -> Medium | Q6: =IFERROR(__xludf.DUMMYFUNCTION("""COMPUTED_VALUE"""),"Converted") -> Converted | R6: =IFERROR(__xludf.DUMMYFUNCTION("""COMPUTED_VALUE"""),"Follow-Up Complete") -> Follow-Up Complete | S6: =IFERROR(__xludf.DUMMYFUNCTION("""COMPUTED_VALUE"""),46254.0) -> 46254 | U6: =IFERROR(__xludf.DUMMYFUNCTION("""COMPUTED_VALUE"""),"Completed") -> Completed | Z6: =IFERROR(__xludf.DUMMYFUNCTION("""COMPUTED_VALUE"""),0.1) -> 0.1 | AA6: =IFERROR(__xludf.DUMMYFUNCTION("""COMPUTED_VALUE"""),0.0) -> 0 | AB6: =IFERROR(__xludf.DUMMYFUNCTION("""COMPUTED_VALUE"""),46235.0) -> 46235
A7: =IFERROR(__xludf.DUMMYFUNCTION("""COMPUTED_VALUE"""),3.0) -> 3 | B7: =IFERROR(__xludf.DUMMYFUNCTION("""COMPUTED_VALUE"""),46264.0) -> 46264 | C7: =IFERROR(__xludf.DUMMYFUNCTION("""COMPUTED_VALUE"""),"Meteoric Pharma") -> Meteoric Pharma | D7: =IFERROR(__xludf.DUMMYFUNCTION("""COMPUTED_VALUE"""),"Mithun Acharya") -> Mithun Acharya | E7: =IFERROR(__xludf.DUMMYFUNCTION("""COMPUTED_VALUE"""),"9227996623") -> 9227996623 | F7: =IFERROR(__xludf.DUMMYFUNCTION("""COMPUTED_VALUE"""),"mithun.it@meteoricbiopharma.com") -> mithun.it@meteoricbiopharma.com | G7: =IFERROR(__xludf.DUMMYFUNCTION("""COMPUTED_VALUE"""),"Ahmedabad") -> Ahmedabad | H7: =IFERROR(__xludf.DUMMYFUNCTION("""COMPUTED_VALUE"""),"India") -> India | I7: =IFERROR(__xludf.DUMMYFUNCTION("""COMPUTED_VALUE"""),"India") -> India | J7: =IFERROR(__xludf.DUMMYFUNCTION("""COMPUTED_VALUE"""),"Service") -> Service | K7: =IFERROR(__xludf.DUMMYFUNCTION("""COMPUTED_VALUE"""),"Healthcare") -> Healthcare | L7: =IFERROR(__xludf.DUMMYFUNCTION("""COMPUTED_VALUE"""),"Pharma") -> Pharma | N7: =IFERROR(__xludf.DUMMYFUNCTION("""COMPUTED_VALUE"""),"Cold Outreach") -> Cold Outreach | O7: =IFERROR(__xludf.DUMMYFUNCTION("""COMPUTED_VALUE"""),"Aastha") -> Aastha | P7: =IFERROR(__xludf.DUMMYFUNCTION("""COMPUTED_VALUE"""),"Hot") -> Hot | Q7: =IFERROR(__xludf.DUMMYFUNCTION("""COMPUTED_VALUE"""),"Proposal Sent") -> Proposal Sent | R7: =IFERROR(__xludf.DUMMYFUNCTION("""COMPUTED_VALUE"""),"Initial Contact") -> Initial Contact | S7: =IFERROR(__xludf.DUMMYFUNCTION("""COMPUTED_VALUE"""),46272.0) -> 46272 | U7: =IFERROR(__xludf.DUMMYFUNCTION("""COMPUTED_VALUE"""),"Not Scheduled") -> Not Scheduled | AA7: =IFERROR(__xludf.DUMMYFUNCTION("""COMPUTED_VALUE"""),0.0) -> 0
A8: =IFERROR(__xludf.DUMMYFUNCTION("""COMPUTED_VALUE"""),37.0) -> 37 | B8: =IFERROR(__xludf.DUMMYFUNCTION("""COMPUTED_VALUE"""),46264.0) -> 46264 | C8: =IFERROR(__xludf.DUMMYFUNCTION("""COMPUTED_VALUE"""),"Anax Lifescience Private Limited") -> Anax Lifescience Private Limited | D8: =IFERROR(__xludf.DUMMYFUNCTION("""COMPUTED_VALUE"""),"Samir Patel (Managing Director)") -> Samir Patel (Managing Director) | E8: =IFERROR(__xludf.DUMMYFUNCTION("""COMPUTED_VALUE"""),"9879105608") -> 9879105608 | F8: =IFERROR(__xludf.DUMMYFUNCTION("""COMPUTED_VALUE"""),"info@anaxlifescience.in") -> info@anaxlifescience.in | G8: =IFERROR(__xludf.DUMMYFUNCTION("""COMPUTED_VALUE"""),"Ahmedabad") -> Ahmedabad | H8: =IFERROR(__xludf.DUMMYFUNCTION("""COMPUTED_VALUE"""),"India") -> India | I8: =IFERROR(__xludf.DUMMYFUNCTION("""COMPUTED_VALUE"""),"India") -> India | J8: =IFERROR(__xludf.DUMMYFUNCTION("""COMPUTED_VALUE"""),"Service") -> Service | K8: =IFERROR(__xludf.DUMMYFUNCTION("""COMPUTED_VALUE"""),"Healthcare") -> Healthcare | L8: =IFERROR(__xludf.DUMMYFUNCTION("""COMPUTED_VALUE"""),"Pharma") -> Pharma | N8: =IFERROR(__xludf.DUMMYFUNCTION("""COMPUTED_VALUE"""),"Event/Expo") -> Event/Expo | O8: =IFERROR(__xludf.DUMMYFUNCTION("""COMPUTED_VALUE"""),"Aastha") -> Aastha | P8: =IFERROR(__xludf.DUMMYFUNCTION("""COMPUTED_VALUE"""),"Cold") -> Cold | Q8: =IFERROR(__xludf.DUMMYFUNCTION("""COMPUTED_VALUE"""),"New") -> New | R8: =IFERROR(__xludf.DUMMYFUNCTION("""COMPUTED_VALUE"""),"Not Started") -> Not Started | U8: =IFERROR(__xludf.DUMMYFUNCTION("""COMPUTED_VALUE"""),"Not Scheduled") -> Not Scheduled | AA8: =IFERROR(__xludf.DUMMYFUNCTION("""COMPUTED_VALUE"""),0.0) -> 0
A9: =IFERROR(__xludf.DUMMYFUNCTION("""COMPUTED_VALUE"""),43.0) -> 43 | B9: =IFERROR(__xludf.DUMMYFUNCTION("""COMPUTED_VALUE"""),46264.0) -> 46264 | C9: =IFERROR(__xludf.DUMMYFUNCTION("""COMPUTED_VALUE"""),"Metropharm Wellness") -> Metropharm Wellness | D9: =IFERROR(__xludf.DUMMYFUNCTION("""COMPUTED_VALUE"""),"Vatsal Dixit (Managing Director)") -> Vatsal Dixit (Managing Director) | E9: =IFERROR(__xludf.DUMMYFUNCTION("""COMPUTED_VALUE"""),"9925249992") -> 9925249992 | F9: =IFERROR(__xludf.DUMMYFUNCTION("""COMPUTED_VALUE"""),"vatsal@metropharmwellness.com") -> vatsal@metropharmwellness.com | G9: =IFERROR(__xludf.DUMMYFUNCTION("""COMPUTED_VALUE"""),"Ahmedabad") -> Ahmedabad | H9: =IFERROR(__xludf.DUMMYFUNCTION("""COMPUTED_VALUE"""),"India") -> India | I9: =IFERROR(__xludf.DUMMYFUNCTION("""COMPUTED_VALUE"""),"India") -> India | J9: =IFERROR(__xludf.DUMMYFUNCTION("""COMPUTED_VALUE"""),"Service") -> Service | K9: =IFERROR(__xludf.DUMMYFUNCTION("""COMPUTED_VALUE"""),"Healthcare") -> Healthcare | L9: =IFERROR(__xludf.DUMMYFUNCTION("""COMPUTED_VALUE"""),"Pharma") -> Pharma | N9: =IFERROR(__xludf.DUMMYFUNCTION("""COMPUTED_VALUE"""),"Event/Expo") -> Event/Expo | O9: =IFERROR(__xludf.DUMMYFUNCTION("""COMPUTED_VALUE"""),"Aastha") -> Aastha | P9: =IFERROR(__xludf.DUMMYFUNCTION("""COMPUTED_VALUE"""),"Cold") -> Cold | Q9: =IFERROR(__xludf.DUMMYFUNCTION("""COMPUTED_VALUE"""),"New") -> New | R9: =IFERROR(__xludf.DUMMYFUNCTION("""COMPUTED_VALUE"""),"Not Started") -> Not Started | U9: =IFERROR(__xludf.DUMMYFUNCTION("""COMPUTED_VALUE"""),"Not Scheduled") -> Not Scheduled | AA9: =IFERROR(__xludf.DUMMYFUNCTION("""COMPUTED_VALUE"""),0.0) -> 0
A10: =IFERROR(__xludf.DUMMYFUNCTION("""COMPUTED_VALUE"""),53.0) -> 53 | B10: =IFERROR(__xludf.DUMMYFUNCTION("""COMPUTED_VALUE"""),46267.0) -> 46267 | C10: =IFERROR(__xludf.DUMMYFUNCTION("""COMPUTED_VALUE"""),"Adilinf") -> Adilinf | D10: =IFERROR(__xludf.DUMMYFUNCTION("""COMPUTED_VALUE"""),"Brijesh Chodavadiya (CEO & Founder)") -> Brijesh Chodavadiya (CEO & Founder) | E10: =IFERROR(__xludf.DUMMYFUNCTION("""COMPUTED_VALUE"""),"9428362964") -> 9428362964 | F10: =IFERROR(__xludf.DUMMYFUNCTION("""COMPUTED_VALUE"""),"brijesh.chodavadiya@adilinf.co.in") -> brijesh.chodavadiya@adilinf.co.in | G10: =IFERROR(__xludf.DUMMYFUNCTION("""COMPUTED_VALUE"""),"Ahmedabad") -> Ahmedabad | H10: =IFERROR(__xludf.DUMMYFUNCTION("""COMPUTED_VALUE"""),"India") -> India | I10: =IFERROR(__xludf.DUMMYFUNCTION("""COMPUTED_VALUE"""),"India") -> India | J10: =IFERROR(__xludf.DUMMYFUNCTION("""COMPUTED_VALUE"""),"Service") -> Service | K10: =IFERROR(__xludf.DUMMYFUNCTION("""COMPUTED_VALUE"""),"Healthcare") -> Healthcare | L10: =IFERROR(__xludf.DUMMYFUNCTION("""COMPUTED_VALUE"""),"Pharma") -> Pharma | N10: =IFERROR(__xludf.DUMMYFUNCTION("""COMPUTED_VALUE"""),"Event/Expo") -> Event/Expo | O10: =IFERROR(__xludf.DUMMYFUNCTION("""COMPUTED_VALUE"""),"Aastha") -> Aastha | P10: =IFERROR(__xludf.DUMMYFUNCTION("""COMPUTED_VALUE"""),"Cold") -> Cold | Q10: =IFERROR(__xludf.DUMMYFUNCTION("""COMPUTED_VALUE"""),"New") -> New | R10: =IFERROR(__xludf.DUMMYFUNCTION("""COMPUTED_VALUE"""),"Not Started") -> Not Started | U10: =IFERROR(__xludf.DUMMYFUNCTION("""COMPUTED_VALUE"""),"Not Scheduled") -> Not Scheduled | AA10: =IFERROR(__xludf.DUMMYFUNCTION("""COMPUTED_VALUE"""),0.0) -> 0
A11: =IFERROR(__xludf.DUMMYFUNCTION("""COMPUTED_VALUE"""),63.0) -> 63 | B11: =IFERROR(__xludf.DUMMYFUNCTION("""COMPUTED_VALUE"""),46267.0) -> 46267 | C11: =IFERROR(__xludf.DUMMYFUNCTION("""COMPUTED_VALUE"""),"NEO India Lifeline Private Limited") -> NEO India Lifeline Private Limited | D11: =IFERROR(__xludf.DUMMYFUNCTION("""COMPUTED_VALUE"""),"Khevna Maniar (HR Manager)") -> Khevna Maniar (HR Manager) | E11: =IFERROR(__xludf.DUMMYFUNCTION("""COMPUTED_VALUE"""),"9898107362") -> 9898107362 | F11: =IFERROR(__xludf.DUMMYFUNCTION("""COMPUTED_VALUE"""),"khevna.maniar@neohealthgroup.com") -> khevna.maniar@neohealthgroup.com | G11: =IFERROR(__xludf.DUMMYFUNCTION("""COMPUTED_VALUE"""),"Ahmedabad") -> Ahmedabad | H11: =IFERROR(__xludf.DUMMYFUNCTION("""COMPUTED_VALUE"""),"India") -> India | I11: =IFERROR(__xludf.DUMMYFUNCTION("""COMPUTED_VALUE"""),"India") -> India | J11: =IFERROR(__xludf.DUMMYFUNCTION("""COMPUTED_VALUE"""),"Service") -> Service | K11: =IFERROR(__xludf.DUMMYFUNCTION("""COMPUTED_VALUE"""),"Healthcare") -> Healthcare | L11: =IFERROR(__xludf.DUMMYFUNCTION("""COMPUTED_VALUE"""),"Pharma") -> Pharma | N11: =IFERROR(__xludf.DUMMYFUNCTION("""COMPUTED_VALUE"""),"Event/Expo") -> Event/Expo | O11: =IFERROR(__xludf.DUMMYFUNCTION("""COMPUTED_VALUE"""),"Aastha") -> Aastha | P11: =IFERROR(__xludf.DUMMYFUNCTION("""COMPUTED_VALUE"""),"Cold") -> Cold | Q11: =IFERROR(__xludf.DUMMYFUNCTION("""COMPUTED_VALUE"""),"New") -> New | R11: =IFERROR(__xludf.DUMMYFUNCTION("""COMPUTED_VALUE"""),"Not Started") -> Not Started | U11: =IFERROR(__xludf.DUMMYFUNCTION("""COMPUTED_VALUE"""),"Not Scheduled") -> Not Scheduled | AA11: =IFERROR(__xludf.DUMMYFUNCTION("""COMPUTED_VALUE"""),0.0) -> 0
A12: =IFERROR(__xludf.DUMMYFUNCTION("""COMPUTED_VALUE"""),72.0) -> 72 | B12: =IFERROR(__xludf.DUMMYFUNCTION("""COMPUTED_VALUE"""),46267.0) -> 46267 | C12: =IFERROR(__xludf.DUMMYFUNCTION("""COMPUTED_VALUE"""),"ICH DIEN WELLNESS / ICH DIEN Nutraceutical") -> ICH DIEN WELLNESS / ICH DIEN Nutraceutical | D12: =IFERROR(__xludf.DUMMYFUNCTION("""COMPUTED_VALUE"""),"Patel Priyen") -> Patel Priyen | E12: =IFERROR(__xludf.DUMMYFUNCTION("""COMPUTED_VALUE"""),"9327000673") -> 9327000673 | F12: =IFERROR(__xludf.DUMMYFUNCTION("""COMPUTED_VALUE"""),"ichdienwellness1970@gmail.com; ichdienwellness.export@gmail.com") -> ichdienwellness1970@gmail.com; ichdienwellness.export@gmail.com | G12: =IFERROR(__xludf.DUMMYFUNCTION("""COMPUTED_VALUE"""),"Palanpur") -> Palanpur | H12: =IFERROR(__xludf.DUMMYFUNCTION("""COMPUTED_VALUE"""),"India") -> India | I12: =IFERROR(__xludf.DUMMYFUNCTION("""COMPUTED_VALUE"""),"India") -> India | J12: =IFERROR(__xludf.DUMMYFUNCTION("""COMPUTED_VALUE"""),"Service") -> Service | K12: =IFERROR(__xludf.DUMMYFUNCTION("""COMPUTED_VALUE"""),"Healthcare") -> Healthcare | L12: =IFERROR(__xludf.DUMMYFUNCTION("""COMPUTED_VALUE"""),"Pharma") -> Pharma | N12: =IFERROR(__xludf.DUMMYFUNCTION("""COMPUTED_VALUE"""),"Event/Expo") -> Event/Expo | O12: =IFERROR(__xludf.DUMMYFUNCTION("""COMPUTED_VALUE"""),"Aastha") -> Aastha | P12: =IFERROR(__xludf.DUMMYFUNCTION("""COMPUTED_VALUE"""),"Cold") -> Cold | Q12: =IFERROR(__xludf.DUMMYFUNCTION("""COMPUTED_VALUE"""),"New") -> New | R12: =IFERROR(__xludf.DUMMYFUNCTION("""COMPUTED_VALUE"""),"Not Started") -> Not Started | U12: =IFERROR(__xludf.DUMMYFUNCTION("""COMPUTED_VALUE"""),"Not Scheduled") -> Not Scheduled | AA12: =IFERROR(__xludf.DUMMYFUNCTION("""COMPUTED_VALUE"""),0.0) -> 0
A13: =IFERROR(__xludf.DUMMYFUNCTION("""COMPUTED_VALUE"""),75.0) -> 75 | B13: =IFERROR(__xludf.DUMMYFUNCTION("""COMPUTED_VALUE"""),46267.0) -> 46267 | C13: =IFERROR(__xludf.DUMMYFUNCTION("""COMPUTED_VALUE"""),"ICH DIEN WELLNESS / ICH DIEN Nutraceutical") -> ICH DIEN WELLNESS / ICH DIEN Nutraceutical | D13: =IFERROR(__xludf.DUMMYFUNCTION("""COMPUTED_VALUE"""),"Rajesh Agrawal (Marketing Manager)") -> Rajesh Agrawal (Marketing Manager) | E13: =IFERROR(__xludf.DUMMYFUNCTION("""COMPUTED_VALUE"""),"7405375350") -> 7405375350 | G13: =IFERROR(__xludf.DUMMYFUNCTION("""COMPUTED_VALUE"""),"Ahmedabad / Palanpur") -> Ahmedabad / Palanpur | H13: =IFERROR(__xludf.DUMMYFUNCTION("""COMPUTED_VALUE"""),"India") -> India | I13: =IFERROR(__xludf.DUMMYFUNCTION("""COMPUTED_VALUE"""),"India") -> India | J13: =IFERROR(__xludf.DUMMYFUNCTION("""COMPUTED_VALUE"""),"Service") -> Service | K13: =IFERROR(__xludf.DUMMYFUNCTION("""COMPUTED_VALUE"""),"Healthcare") -> Healthcare | L13: =IFERROR(__xludf.DUMMYFUNCTION("""COMPUTED_VALUE"""),"Pharma") -> Pharma | N13: =IFERROR(__xludf.DUMMYFUNCTION("""COMPUTED_VALUE"""),"Event/Expo") -> Event/Expo | O13: =IFERROR(__xludf.DUMMYFUNCTION("""COMPUTED_VALUE"""),"Aastha") -> Aastha | P13: =IFERROR(__xludf.DUMMYFUNCTION("""COMPUTED_VALUE"""),"Hot") -> Hot | Q13: =IFERROR(__xludf.DUMMYFUNCTION("""COMPUTED_VALUE"""),"Negotiation") -> Negotiation | R13: =IFERROR(__xludf.DUMMYFUNCTION("""COMPUTED_VALUE"""),"Not Started") -> Not Started | U13: =IFERROR(__xludf.DUMMYFUNCTION("""COMPUTED_VALUE"""),"Not Scheduled") -> Not Scheduled | AA13: =IFERROR(__xludf.DUMMYFUNCTION("""COMPUTED_VALUE"""),0.0) -> 0
A14: =IFERROR(__xludf.DUMMYFUNCTION("""COMPUTED_VALUE"""),76.0) -> 76 | B14: =IFERROR(__xludf.DUMMYFUNCTION("""COMPUTED_VALUE"""),46267.0) -> 46267 | C14: =IFERROR(__xludf.DUMMYFUNCTION("""COMPUTED_VALUE"""),"Religence Pharmaceuticals Private Limited") -> Religence Pharmaceuticals Private Limited | D14: =IFERROR(__xludf.DUMMYFUNCTION("""COMPUTED_VALUE"""),"Mohit Patel") -> Mohit Patel | E14: =IFERROR(__xludf.DUMMYFUNCTION("""COMPUTED_VALUE"""),"9825966650; 9727173573") -> 9825966650; 9727173573 | F14: =IFERROR(__xludf.DUMMYFUNCTION("""COMPUTED_VALUE"""),"mohit@religence.in; info@religence.in") -> mohit@religence.in; info@religence.in | G14: =IFERROR(__xludf.DUMMYFUNCTION("""COMPUTED_VALUE"""),"Bhavnagar / Bharuch") -> Bhavnagar / Bharuch | H14: =IFERROR(__xludf.DUMMYFUNCTION("""COMPUTED_VALUE"""),"India") -> India | I14: =IFERROR(__xludf.DUMMYFUNCTION("""COMPUTED_VALUE"""),"India") -> India | J14: =IFERROR(__xludf.DUMMYFUNCTION("""COMPUTED_VALUE"""),"Service") -> Service | K14: =IFERROR(__xludf.DUMMYFUNCTION("""COMPUTED_VALUE"""),"Healthcare") -> Healthcare | L14: =IFERROR(__xludf.DUMMYFUNCTION("""COMPUTED_VALUE"""),"Pharma") -> Pharma | N14: =IFERROR(__xludf.DUMMYFUNCTION("""COMPUTED_VALUE"""),"Event/Expo") -> Event/Expo | O14: =IFERROR(__xludf.DUMMYFUNCTION("""COMPUTED_VALUE"""),"Aastha") -> Aastha | P14: =IFERROR(__xludf.DUMMYFUNCTION("""COMPUTED_VALUE"""),"Cold") -> Cold | Q14: =IFERROR(__xludf.DUMMYFUNCTION("""COMPUTED_VALUE"""),"New") -> New | R14: =IFERROR(__xludf.DUMMYFUNCTION("""COMPUTED_VALUE"""),"Not Started") -> Not Started | U14: =IFERROR(__xludf.DUMMYFUNCTION("""COMPUTED_VALUE"""),"Not Scheduled") -> Not Scheduled | AA14: =IFERROR(__xludf.DUMMYFUNCTION("""COMPUTED_VALUE"""),0.0) -> 0
A15: =IFERROR(__xludf.DUMMYFUNCTION("""COMPUTED_VALUE"""),77.0) -> 77 | B15: =IFERROR(__xludf.DUMMYFUNCTION("""COMPUTED_VALUE"""),46267.0) -> 46267 | C15: =IFERROR(__xludf.DUMMYFUNCTION("""COMPUTED_VALUE"""),"Decefrag Pharmaceuticals") -> Decefrag Pharmaceuticals | D15: =IFERROR(__xludf.DUMMYFUNCTION("""COMPUTED_VALUE"""),"Mahek Thakur (Global Sales Manager)") -> Mahek Thakur (Global Sales Manager) | E15: =IFERROR(__xludf.DUMMYFUNCTION("""COMPUTED_VALUE"""),"9924627787") -> 9924627787 | F15: =IFERROR(__xludf.DUMMYFUNCTION("""COMPUTED_VALUE"""),"mahek.thakur@decefragpharma.com; mahek.singh2204@gmail.com") -> mahek.thakur@decefragpharma.com; mahek.singh2204@gmail.com | G15: =IFERROR(__xludf.DUMMYFUNCTION("""COMPUTED_VALUE"""),"Ahmedabad") -> Ahmedabad | H15: =IFERROR(__xludf.DUMMYFUNCTION("""COMPUTED_VALUE"""),"India") -> India | I15: =IFERROR(__xludf.DUMMYFUNCTION("""COMPUTED_VALUE"""),"India") -> India | J15: =IFERROR(__xludf.DUMMYFUNCTION("""COMPUTED_VALUE"""),"Service") -> Service | K15: =IFERROR(__xludf.DUMMYFUNCTION("""COMPUTED_VALUE"""),"Healthcare") -> Healthcare | L15: =IFERROR(__xludf.DUMMYFUNCTION("""COMPUTED_VALUE"""),"Pharma") -> Pharma | N15: =IFERROR(__xludf.DUMMYFUNCTION("""COMPUTED_VALUE"""),"Event/Expo") -> Event/Expo | O15: =IFERROR(__xludf.DUMMYFUNCTION("""COMPUTED_VALUE"""),"Aastha") -> Aastha | P15: =IFERROR(__xludf.DUMMYFUNCTION("""COMPUTED_VALUE"""),"Cold") -> Cold | Q15: =IFERROR(__xludf.DUMMYFUNCTION("""COMPUTED_VALUE"""),"New") -> New | R15: =IFERROR(__xludf.DUMMYFUNCTION("""COMPUTED_VALUE"""),"Not Started") -> Not Started | U15: =IFERROR(__xludf.DUMMYFUNCTION("""COMPUTED_VALUE"""),"Not Scheduled") -> Not Scheduled | AA15: =IFERROR(__xludf.DUMMYFUNCTION("""COMPUTED_VALUE"""),0.0) -> 0
