Workbook

Sheet Dashboard
B1: TechSentinals Founder OS
B3: CURRENT BALANCE | D3: TOTAL REVENUE | F3: TOTAL EXPENSES | H3: RUNWAY (MONTHS) | J3: GRANTS OVERVIEW
B4: =SUM(Income!F:F) + SUM(Grants!F:F) - SUM(Expenses!E:E) -> 342686.66 | D4: =SUM(Income!F:F) + SUM(Grants!F:F) -> 509400 | F4: =SUM(Expenses!E:E) -> 166713.34 | H4: =IF(SUM(Expenses!E:E)>0, (1000000+SUM(Income!F:F)-SUM(Expenses!E:E))/(SUM(Expenses!E:E)/12), "Infinite") -> 89.44839 | J4: Total Requested | K4: =SUM(Grants!E:E) -> 250000
J5: Total Received | K5: =SUM(Grants!F:F) -> 100000
J6: Pending Amount | K6: =K4-K5 -> 150000
J8: Grant Money Used | K8: =SUMIFS(Expenses!E:E, Expenses!D:D, "Grant") -> 92175.32

Sheet Income
A1: Date | B1: Invoice ID | C1: Client | D1: Project | E1: Category | F1: Amount | G1: Payment Mode | H1: Status | I1: Notes
A2: 45700 | C2: TechSentinals | E2: Other | F2: 20000 | G2: Bank Transfer | H2: Completed | I2: Combine Amount By All 4
A3: 45700 | C3: TechSentinals | E3: Other | F3: 100 | G3: Bank Transfer | H3: Completed | I3: Vansh Puts Amount to check
A4: 18/02/2026 | C4: TechSentinals | E4: Other | F4: 5000 | G4: Bank Transfer | H4: Completed | I4: Hackhathon Money
A5: 27/03/2026 | C5: Inventa Systems | D5: Invents Webiste | E5: Product Sales | F5: 22500 | G5: Bank Transfer | H5: Completed | I5: Inventa Half Payment
A6: 46207 | C6: TechSentinals | E6: Other | F6: 10000 | G6: Bank Transfer | H6: Completed | I6: Hackhathon Money
A7: 46147 | C7: RotoTech Systems | D7: Rototech custom devp | E7: Product Sales | F7: 75000 | G7: Bank Transfer | H7: Completed | I7: Rototech half money
A8: 13/05/2026 | C8: TechSentinals | E8: Other | F8: 11000 | G8: Bank Transfer | H8: Completed | I8: Data Manthan money
A9: 46060 | C9: Inventa Systems | D9: Invents Webiste | E9: Product Sales | F9: 22500 | G9: Bank Transfer | H9: Completed | I9: Invents Other Half
A10: 46088 | C10: RotoTech Systems | D10: Rototech custom devp | E10: Product Sales | F10: 50000 | G10: Bank Transfer | H10: Completed | I10: Rototech other some money
A11: 31/07/2026 | C11: RotoTech Systems | D11: Rototech custom devp | E11: Product Sales | F11: 25000 | G11: Bank Transfer | H11: Completed | I11: Rototech phase 1 completed
A12: 46364 | C12: RotoTech Phase 2 | D12: Rototech custom phase 2 | E12: Product Sales | F12: 25000 | G12: Bank Transfer | H12: Completed | I12: Rototech phase 2 advance.
A13: 18/08/2026 | C13: TechSentinals | E13: Other | F13: 1400 | G13: Bank Transfer | H13: Completed | I13: vansh puts back banner
A14: 46090 | C14: Strikar lifescience llp | D14: strikar lifescience | E14: Product Sales | F14: 39000 | G14: Bank Transfer | H14: Completed | I14: strikar lifescience 1st trench
A15: 22/09/2026 | C15: Vishalwin foundation | D15: vishalwin | E15: Other | F15: 102900 | G15: Bank Transfer | H15: Completed | I15: Vishalwin foundation 1st trench

Sheet Bank Transactions
A1: Date | B1: Description | C1: Reference No | D1: Withdrawal | E1: Deposit | F1: Balance | G1: Type | H1: Matched Status | I1: Match Note
G2: =IF(ISBLANK(A2), "", IF(D2>0, "Expense", IF(E2>0, "Income", ""))) | H2: =IF(ISBLANK(A2), "", IF(D2>0, IF(COUNTIF(Expenses!E:E, D2)>0, "Matched", "Unmatched"), IF(E2>0, IF(COUNTIF(Income!F:F, E2)>0, "Matched", "Unmatched"), "")))
G3: =IF(ISBLANK(A3), "", IF(D3>0, "Expense", IF(E3>0, "Income", ""))) | H3: =IF(ISBLANK(A3), "", IF(D3>0, IF(COUNTIF(Expenses!E:E, D3)>0, "Matched", "Unmatched"), IF(E3>0, IF(COUNTIF(Income!F:F, E3)>0, "Matched", "Unmatched"), "")))
G4: =IF(ISBLANK(A4), "", IF(D4>0, "Expense", IF(E4>0, "Income", ""))) | H4: =IF(ISBLANK(A4), "", IF(D4>0, IF(COUNTIF(Expenses!E:E, D4)>0, "Matched", "Unmatched"), IF(E4>0, IF(COUNTIF(Income!F:F, E4)>0, "Matched", "Unmatched"), "")))
G5: =IF(ISBLANK(A5), "", IF(D5>0, "Expense", IF(E5>0, "Income", ""))) | H5: =IF(ISBLANK(A5), "", IF(D5>0, IF(COUNTIF(Expenses!E:E, D5)>0, "Matched", "Unmatched"), IF(E5>0, IF(COUNTIF(Income!F:F, E5)>0, "Matched", "Unmatched"), "")))
G6: =IF(ISBLANK(A6), "", IF(D6>0, "Expense", IF(E6>0, "Income", ""))) | H6: =IF(ISBLANK(A6), "", IF(D6>0, IF(COUNTIF(Expenses!E:E, D6)>0, "Matched", "Unmatched"), IF(E6>0, IF(COUNTIF(Income!F:F, E6)>0, "Matched", "Unmatched"), "")))
G7: =IF(ISBLANK(A7), "", IF(D7>0, "Expense", IF(E7>0, "Income", ""))) | H7: =IF(ISBLANK(A7), "", IF(D7>0, IF(COUNTIF(Expenses!E:E, D7)>0, "Matched", "Unmatched"), IF(E7>0, IF(COUNTIF(Income!F:F, E7)>0, "Matched", "Unmatched"), "")))
G8: =IF(ISBLANK(A8), "", IF(D8>0, "Expense", IF(E8>0, "Income", ""))) | H8: =IF(ISBLANK(A8), "", IF(D8>0, IF(COUNTIF(Expenses!E:E, D8)>0, "Matched", "Unmatched"), IF(E8>0, IF(COUNTIF(Income!F:F, E8)>0, "Matched", "Unmatched"), "")))
G9: =IF(ISBLANK(A9), "", IF(D9>0, "Expense", IF(E9>0, "Income", ""))) | H9: =IF(ISBLANK(A9), "", IF(D9>0, IF(COUNTIF(Expenses!E:E, D9)>0, "Matched", "Unmatched"), IF(E9>0, IF(COUNTIF(Income!F:F, E9)>0, "Matched", "Unmatched"), "")))
G10: =IF(ISBLANK(A10), "", IF(D10>0, "Expense", IF(E10>0, "Income", ""))) | H10: =IF(ISBLANK(A10), "", IF(D10>0, IF(COUNTIF(Expenses!E:E, D10)>0, "Matched", "Unmatched"), IF(E10>0, IF(COUNTIF(Income!F:F, E10)>0, "Matched", "Unmatched"), "")))
G11: =IF(ISBLANK(A11), "", IF(D11>0, "Expense", IF(E11>0, "Income", ""))) | H11: =IF(ISBLANK(A11), "", IF(D11>0, IF(COUNTIF(Expenses!E:E, D11)>0, "Matched", "Unmatched"), IF(E11>0, IF(COUNTIF(Income!F:F, E11)>0, "Matched", "Unmatched"), "")))
G12: =IF(ISBLANK(A12), "", IF(D12>0, "Expense", IF(E12>0, "Income", ""))) | H12: =IF(ISBLANK(A12), "", IF(D12>0, IF(COUNTIF(Expenses!E:E, D12)>0, "Matched", "Unmatched"), IF(E12>0, IF(COUNTIF(Income!F:F, E12)>0, "Matched", "Unmatched"), "")))
G13: =IF(ISBLANK(A13), "", IF(D13>0, "Expense", IF(E13>0, "Income", ""))) | H13: =IF(ISBLANK(A13), "", IF(D13>0, IF(COUNTIF(Expenses!E:E, D13)>0, "Matched", "Unmatched"), IF(E13>0, IF(COUNTIF(Income!F:F, E13)>0, "Matched", "Unmatched"), "")))
... G1000: =IF(ISBLANK(A1000), "", IF(D1000>0, "Expense", IF(E1000>0, "Income", ""))) | H1000: =IF(ISBLANK(A1000), "", IF(D1000>0, IF(COUNTIF(Expenses!E:E, D1000)>0, "Matched", "Unmatched"), IF(E1000>0, IF(COUNTIF(Income!F:F, E1000)>0, "Matched", "Unmatched"), "")))

Sheet Expenses
A1: Date | B1: Expense ID | C1: Vendor | D1: Category | E1: Amount | F1: Payment Mode | G1: Status | H1: Receipt Link | I1: Notes
A2: 14/12/2025 | D2: Marketing | E2: 472 | F2: Debit Card | G2: Completed
A3: 46174 | D3: Other | E3: 2.65 | G3: Completed | I3: Bank Charges
A4: 46327 | D4: Other | E4: 118 | G4: Completed | I4: Bank Charges
A5: 27/01/2026 | D5: Marketing | E5: 500 | F5: Debit Card | G5: Completed | I5: For Monthly Recharge
A6: 27/01/2026 | D6: Other | E6: 27.14 | G6: Completed | I6: Bank Charges
A7: 19/02/2026 | D7: Marketing | E7: 5500 | F7: Debit Card | G7: Completed | I7: Marketing for hospex
A8: 19/02/2026 | D8: Other | E8: 27.14 | G8: Completed | I8: Bank Charges
A9: 15/03/2026 | D9: Other | E9: 380 | F9: Debit Card | G9: Completed | I9: Recharge
A10: 28/03/2026 | D10: Marketing | E10: 1300 | F10: Debit Card | G10: Completed
A11: 28/03/2026 | D11: Other | E11: 27.14 | G11: Completed | I11: Bank Charges
A12: 30/03/2026 | D12: Marketing | E12: 1500 | F12: Bank Transfer | G12: Completed | I12: Paid to Vansh
A13: 46330 | D13: Other | E13: 3.24 | G13: Completed | I13: Bank Charges
A14: 46360 | D14: Other | E14: 118 | G14: Completed | I14: Bank Charges
A15: 15/04/2026 | D15: Marketing | E15: 1000 | F15: Bank Transfer | G15: Completed | I15: Paid to Vansh
A16: 26/04/2026 | D16: Marketing | E16: 500 | F16: Bank Transfer | G16: Completed | I16: recharge
A17: 46361 | D17: Software/SaaS | E17: 2350 | F17: Bank Transfer | G17: Completed | I17: Claude Subscription
A18: 25/05/2026 | D18: Marketing | E18: 500 | F18: Bank Transfer | G18: Completed | I18: recharge
A19: 46059 | D19: Hardware | E19: 13000 | F19: Bank Transfer | G19: Completed | I19: Laptop repair
A20: 46301 | D20: Marketing | E20: 1000 | F20: Bank Transfer | G20: Completed | I20: Paid to Vansh
A21: 13/06/2026 | D21: Software/SaaS | E21: 2350 | F21: Bank Transfer | G21: Completed | I21: Claude Subscription
A22: 27/06/2026 | D22: Marketing | E22: 500 | F22: Bank Transfer | G22: Completed | I22: recharge
A23: 46149 | D23: Other | E23: 9.73 | G23: Completed | I23: bank Charges
A24: 13/07/2026 | D24: Grant | E24: 2350 | F24: Bank Transfer | G24: Completed | I24: Claude Subscription
A25: 13/07/2026 | D25: Travel | E25: 5000 | F25: Bank Transfer | G25: Completed | I25: Office
A26: 17/07/2026 | D26: Other | E26: 12.98 | G26: Completed | I26: bank Charges
A27: 18/07/2026 | D27: Grant | E27: 35669.04 | F27: Debit Card | G27: Completed | I27: Server
A28: 18/07/2026 | D28: Grant | E28: 6370.82 | F28: Debit Card | G28: Completed | I28: Domain
A29: 26/07/2026 | D29: Marketing | E29: 500 | F29: Bank Transfer | G29: Completed | I29: recharge
A30: 28/07/2026 | D30: Other | E30: 2 | G30: Completed | I30: bank Charges
A31: 29/07/2026 | D31: Grant | E31: 1770 | F31: Bank Transfer | G31: Completed | I31: standee
A32: 29/07/2026 | D32: Office/Rent | E32: 550 | F32: Bank Transfer | G32: Completed | I32: e stamp
A33: 03/08.2026 | D33: Payroll | E33: 5600 | F33: Bank Transfer | G33: Completed | I33: Jenil amount
A34: 46120 | D34: Grant | E34: 12400 | F34: Bank Transfer | G34: Completed | I34: ssd vansh
A35: 46303 | D35: Other | E35: 18520 | F35: Bank Transfer | G35: Completed | I35: Utility Patent
A36: 46303 | D36: Grant | E36: 3182.46 | F36: Debit Card | G36: Completed | I36: techsentinals domain retain
A37: 46334 | D37: Other | E37: 500 | F37: Bank Transfer | G37: Completed | I37: to ashwin for ssd
A38: 46334 | D38: Grant | E38: 10500 | F38: Bank Transfer | G38: Completed | I38: ssd to ashwin
A39: 46364 | D39: Grant | E39: 2350 | F39: Bank Transfer | G39: Completed | I39: claude Subscription
A40: 17/08/2026 | D40: Grant | E40: 2350 | F40: Bank Transfer | G40: Completed | I40: claude Subscription
...

Sheet Clients
A1: Client ID | B1: Client Name | C1: Contact Person | D1: Email | E1: Phone | F1: Status | G1: Total Billed
B2: Inventa Systems | F2: Completed | G2: 45000
B3: RotoTech Systems | F3: Completed | G3: 1,50,000.00
B4: TechSentinals | F4: Completed | G4: 46100
B5: RotoTech Phase 2 | F5: Active
B6: Strikar lifescience llp | F6: Active
B7: Vishalwin foundation | F7: Active

Sheet Projects
A1: Project ID | B1: Project Name | C1: Client | D1: Status | E1: Start Date | F1: End Date | G1: Budget | H1: Total Billed | I1: Total Expenses | J1: Profitability | K1: Project Manager
B2: Invents Webiste | C2: Inventa Systems | D2: Completed | H2: 45000 | K2: Ashwin Solanki
B3: Rototech custom devp | C3: RotoTech Systems | D3: Completed | H3: 1,50,000 | K3: Ashwin Solanki
B4: Rototech custom phase 2 | C4: TechSentinals | D4: Active | K4: Ashwin Solanki
B5: strikar lifescience | C5: Strikar lifescience llp | D5: Active | K5: Ashwin Solanki
B6: vishalwin | C6: Vishalwin foundation | D6: Active

Sheet Assets
A1: Asset ID | B1: Asset Type | C1: Make/Model | D1: Serial Number | E1: Purchase Date | F1: Purchase Value | G1: Current Value | H1: Assigned To | I1: Status | J1: Notes

Sheet Subscriptions
A1: Subscription ID | B1: Software/Service | C1: Category | D1: Monthly Cost | E1: Annual Cost | F1: Renewal Date | G1: Owner | H1: Status | I1: Notes
B2: Claude Subscription | D2: 2399 | F2: 12th of every month | G2: Ashwin Solanki | H2: Active
B3: Claude Subscription | D3: 2399 | F3: 17th of every month | G3: Ashwin Solanki | H3: Active
B4: Chatgpt Plus | D4: 2000 | F4: 6th of every month | G4: Vansh Balyan | H4: Active

Sheet Grants
A1: Grant ID | B1: Grant Name | C1: Funder | D1: Application Date | E1: Amount Requested | F1: Amount Received | G1: Status | H1: Next Reporting Date | I1: Notes
A2: 1 | B2: SSIP | C2: LEAF GLS | E2: 250000 | F2: 100000 | G2: Disbursed

Sheet Documents
A1: Document ID | B1: Document Name | C1: Category | D1: Upload Date | E1: Expiry Date | F1: Link/Location | G1: Status | H1: Owner | I1: Notes

Sheet Analytics
A1: Expense Category | B1: Total Amount | D1: Client | E1: Total Revenue
A2: {=INDEX(Settings!B2:B11, ROW()-1)} -> Payroll | B2: =SUMIF(Expenses!$D:$D, A2, Expenses!$E:$E) -> 5600 | D2: {=IF(ISBLANK(INDEX(Clients!B2:B21, ROW()-1)), "", INDEX(Clients!B2:B21, ROW()-1))} -> Inventa Systems | E2: =IF(ISBLANK(D2), "", SUMIF(Income!$C:$C, D2, Income!$F:$F)) -> 45000
A3: {=INDEX(Settings!B3:B12, ROW()-1)} -> Marketing | B3: =SUMIF(Expenses!$D:$D, A3, Expenses!$E:$E) -> 13272 | D3: {=IF(ISBLANK(INDEX(Clients!B3:B22, ROW()-1)), "", INDEX(Clients!B3:B22, ROW()-1))} -> TechSentinals | E3: =IF(ISBLANK(D3), "", SUMIF(Income!$C:$C, D3, Income!$F:$F)) -> 47500
A4: {=INDEX(Settings!B4:B13, ROW()-1)} -> Travel | B4: =SUMIF(Expenses!$D:$D, A4, Expenses!$E:$E) -> 5000 | D4: {=IF(ISBLANK(INDEX(Clients!B4:B23, ROW()-1)), "", INDEX(Clients!B4:B23, ROW()-1))} -> Strikar lifescience llp | E4: =IF(ISBLANK(D4), "", SUMIF(Income!$C:$C, D4, Income!$F:$F)) -> 39000
A5: {=INDEX(Settings!B5:B14, ROW()-1)} -> Hardware | B5: =SUMIF(Expenses!$D:$D, A5, Expenses!$E:$E) -> 13000 | D5: {=IF(ISBLANK(INDEX(Clients!B5:B24, ROW()-1)), "", INDEX(Clients!B5:B24, ROW()-1))} | E5: =IF(ISBLANK(D5), "", SUMIF(Income!$C:$C, D5, Income!$F:$F)) -> 0
A6: {=INDEX(Settings!B6:B15, ROW()-1)} -> Other | B6: =SUMIF(Expenses!$D:$D, A6, Expenses!$E:$E) -> 32416.02 | D6: {=IF(ISBLANK(INDEX(Clients!B6:B25, ROW()-1)), "", INDEX(Clients!B6:B25, ROW()-1))} | E6: =IF(ISBLANK(D6), "", SUMIF(Income!$C:$C, D6, Income!$F:$F)) -> 0
A7: {=INDEX(Settings!B7:B16, ROW()-1)} | B7: =SUMIF(Expenses!$D:$D, A7, Expenses!$E:$E) -> 0 | D7: {=IF(ISBLANK(INDEX(Clients!B7:B26, ROW()-1)), "", INDEX(Clients!B7:B26, ROW()-1))} | E7: =IF(ISBLANK(D7), "", SUMIF(Income!$C:$C, D7, Income!$F:$F)) -> 0
A8: {=INDEX(Settings!B8:B17, ROW()-1)} | B8: =SUMIF(Expenses!$D:$D, A8, Expenses!$E:$E) -> 0 | D8: {=IF(ISBLANK(INDEX(Clients!B8:B27, ROW()-1)), "", INDEX(Clients!B8:B27, ROW()-1))} | E8: =IF(ISBLANK(D8), "", SUMIF(Income!$C:$C, D8, Income!$F:$F)) -> 0
A9: {=INDEX(Settings!B9:B18, ROW()-1)} | B9: =SUMIF(Expenses!$D:$D, A9, Expenses!$E:$E) -> 0 | D9: {=IF(ISBLANK(INDEX(Clients!B9:B28, ROW()-1)), "", INDEX(Clients!B9:B28, ROW()-1))} | E9: =IF(ISBLANK(D9), "", SUMIF(Income!$C:$C, D9, Income!$F:$F)) -> 0
A10: {=INDEX(Settings!B10:B19, ROW()-1)} | B10: =SUMIF(Expenses!$D:$D, A10, Expenses!$E:$E) -> 0 | D10: {=IF(ISBLANK(INDEX(Clients!B10:B29, ROW()-1)), "", INDEX(Clients!B10:B29, ROW()-1))} | E10: =IF(ISBLANK(D10), "", SUMIF(Income!$C:$C, D10, Income!$F:$F)) -> 0
A11: {=INDEX(Settings!B11:B20, ROW()-1)} | B11: =SUMIF(Expenses!$D:$D, A11, Expenses!$E:$E) -> 0 | D11: {=IF(ISBLANK(INDEX(Clients!B11:B30, ROW()-1)), "", INDEX(Clients!B11:B30, ROW()-1))} | E11: =IF(ISBLANK(D11), "", SUMIF(Income!$C:$C, D11, Income!$F:$F)) -> 0
D12: {=IF(ISBLANK(INDEX(Clients!B12:B31, ROW()-1)), "", INDEX(Clients!B12:B31, ROW()-1))} | E12: =IF(ISBLANK(D12), "", SUMIF(Income!$C:$C, D12, Income!$F:$F)) -> 0
D13: {=IF(ISBLANK(INDEX(Clients!B13:B32, ROW()-1)), "", INDEX(Clients!B13:B32, ROW()-1))} | E13: =IF(ISBLANK(D13), "", SUMIF(Income!$C:$C, D13, Income!$F:$F)) -> 0
D14: {=IF(ISBLANK(INDEX(Clients!B14:B33, ROW()-1)), "", INDEX(Clients!B14:B33, ROW()-1))} | E14: =IF(ISBLANK(D14), "", SUMIF(Income!$C:$C, D14, Income!$F:$F)) -> 0
D15: {=IF(ISBLANK(INDEX(Clients!B15:B34, ROW()-1)), "", INDEX(Clients!B15:B34, ROW()-1))} | E15: =IF(ISBLANK(D15), "", SUMIF(Income!$C:$C, D15, Income!$F:$F)) -> 0
D16: {=IF(ISBLANK(INDEX(Clients!B16:B35, ROW()-1)), "", INDEX(Clients!B16:B35, ROW()-1))} | E16: =IF(ISBLANK(D16), "", SUMIF(Income!$C:$C, D16, Income!$F:$F)) -> 0
D17: {=IF(ISBLANK(INDEX(Clients!B17:B36, ROW()-1)), "", INDEX(Clients!B17:B36, ROW()-1))} | E17: =IF(ISBLANK(D17), "", SUMIF(Income!$C:$C, D17, Income!$F:$F)) -> 0
D18: {=IF(ISBLANK(INDEX(Clients!B18:B37, ROW()-1)), "", INDEX(Clients!B18:B37, ROW()-1))} | E18: =IF(ISBLANK(D18), "", SUMIF(Income!$C:$C, D18, Income!$F:$F)) -> 0
D19: {=IF(ISBLANK(INDEX(Clients!B19:B38, ROW()-1)), "", INDEX(Clients!B19:B38, ROW()-1))} | E19: =IF(ISBLANK(D19), "", SUMIF(Income!$C:$C, D19, Income!$F:$F)) -> 0
D20: {=IF(ISBLANK(INDEX(Clients!B20:B39, ROW()-1)), "", INDEX(Clients!B20:B39, ROW()-1))} | E20: =IF(ISBLANK(D20), "", SUMIF(Income!$C:$C, D20, Income!$F:$F)) -> 0
D21: {=IF(ISBLANK(INDEX(Clients!B21:B40, ROW()-1)), "", INDEX(Clients!B21:B40, ROW()-1))} | E21: =IF(ISBLANK(D21), "", SUMIF(Income!$C:$C, D21, Income!$F:$F)) -> 0

Sheet Settings
A1: Income Categories | B1: Expense Categories | C1: Statuses | D1: Payment Modes | E1: Team Members | F1: Grant Status
A2: Consulting | B2: Payroll | C2: Active | D2: Bank Transfer | E2: Vansh Balyan | F2: Applied
A3: Product Sales | B3: Software/SaaS | C3: Completed | D3: Credit Card | E3: Ashwin Solanki | F3: Approved
A4: Retainer | B4: Marketing | C4: On Hold | D4: Debit Card | E4: Dhruv Solanki | F4: Disbursed
A5: Grant | B5: Office/Rent | C5: Cancelled | D5: UPI | E5: Aastha Sangtani | F5: Closed
A6: Investment | B6: Travel | C6: Pending | D6: Cash | F6: Rejected
A7: Other | B7: Legal & Admin | C7: At Risk | D7: Stripe
B8: Hardware | D8: PayPal
B9: Hosting/Cloud
B10: Other
B11: Grant
